/home/olcaey/koytola/venv/lib/python3.8/site-packages/graphene_django/types.py:94: UserWarning: Field name "description" doesn't exist on Django model "profile.Certificate". Consider removing the field from the "fields" list of DjangoObjectType "Certificate" because it has no effect.
  warnings.warn(
/home/olcaey/koytola/venv/lib/python3.8/site-packages/graphene_django/types.py:94: UserWarning: Field name "name" doesn't exist on Django model "profile.Certificate". Consider removing the field from the "fields" list of DjangoObjectType "Certificate" because it has no effect.
  warnings.warn(
/home/olcaey/koytola/venv/lib/python3.8/site-packages/graphene_django/types.py:94: UserWarning: Field name "content" doesn't exist on Django model "blog.Blog". Consider removing the field from the "fields" list of DjangoObjectType "BlogTranslatableContent" because it has no effect.
  warnings.warn(
/home/olcaey/koytola/venv/lib/python3.8/site-packages/graphene_django/types.py:94: UserWarning: Field name "summary" doesn't exist on Django model "blog.Blog". Consider removing the field from the "fields" list of DjangoObjectType "BlogTranslatableContent" because it has no effect.
  warnings.warn(
/home/olcaey/koytola/venv/lib/python3.8/site-packages/graphene_django/types.py:94: UserWarning: Field name "content_plaintext" doesn't exist on Django model "news.News". Consider removing the field from the "fields" list of DjangoObjectType "NewsTranslatableContent" because it has no effect.
  warnings.warn(
/home/olcaey/koytola/venv/lib/python3.8/site-packages/graphene_django/types.py:94: UserWarning: Field name "description" doesn't exist on Django model "news.News". Consider removing the field from the "fields" list of DjangoObjectType "News" because it has no effect.
  warnings.warn(
[2021-08-09 10:49:35,286: INFO/MainProcess] Connected to redis://localhost:6379/1
[2021-08-09 10:49:35,300: INFO/MainProcess] mingle: searching for neighbors
[2021-08-09 10:49:36,328: WARNING/MainProcess] /home/olcaey/koytola/venv/lib/python3.8/site-packages/celery/app/control.py:52: DuplicateNodenameWarning: Received multiple replies from node name: celery@koytola-dev.
Please make sure you give each node a unique nodename using
the celery worker `-n` option.
  warnings.warn(DuplicateNodenameWarning(
[2021-08-09 10:49:36,328: INFO/MainProcess] mingle: all alone
[2021-08-09 10:49:36,348: INFO/MainProcess] celery@koytola-dev ready.
[2021-08-09 11:00:27,912: WARNING/MainProcess] consumer: Connection to broker lost. Trying to re-establish the connection...
Traceback (most recent call last):
  File "/home/olcaey/koytola/venv/lib/python3.8/site-packages/celery/worker/consumer/consumer.py", line 318, in start
    blueprint.start(self)
  File "/home/olcaey/koytola/venv/lib/python3.8/site-packages/celery/bootsteps.py", line 119, in start
    step.start(parent)
  File "/home/olcaey/koytola/venv/lib/python3.8/site-packages/celery/worker/consumer/consumer.py", line 599, in start
    c.loop(*c.loop_args())
  File "/home/olcaey/koytola/venv/lib/python3.8/site-packages/celery/worker/loops.py", line 83, in asynloop
    next(loop)
  File "/home/olcaey/koytola/venv/lib/python3.8/site-packages/kombu/asynchronous/hub.py", line 364, in create_loop
    cb(*cbargs)
  File "/home/olcaey/koytola/venv/lib/python3.8/site-packages/kombu/transport/redis.py", line 1083, in on_readable
    self.cycle.on_readable(fileno)
  File "/home/olcaey/koytola/venv/lib/python3.8/site-packages/kombu/transport/redis.py", line 354, in on_readable
    chan.handlers[type]()
  File "/home/olcaey/koytola/venv/lib/python3.8/site-packages/kombu/transport/redis.py", line 688, in _receive
    ret.append(self._receive_one(c))
  File "/home/olcaey/koytola/venv/lib/python3.8/site-packages/kombu/transport/redis.py", line 698, in _receive_one
    response = c.parse_response()
  File "/home/olcaey/koytola/venv/lib/python3.8/site-packages/redis/client.py", line 3505, in parse_response
    response = self._execute(conn, conn.read_response)
  File "/home/olcaey/koytola/venv/lib/python3.8/site-packages/redis/client.py", line 3479, in _execute
    return command(*args, **kwargs)
  File "/home/olcaey/koytola/venv/lib/python3.8/site-packages/redis/connection.py", line 739, in read_response
    response = self._parser.read_response()
  File "/home/olcaey/koytola/venv/lib/python3.8/site-packages/redis/connection.py", line 324, in read_response
    raw = self._buffer.readline()
  File "/home/olcaey/koytola/venv/lib/python3.8/site-packages/redis/connection.py", line 256, in readline
    self._read_from_socket()
  File "/home/olcaey/koytola/venv/lib/python3.8/site-packages/redis/connection.py", line 201, in _read_from_socket
    raise ConnectionError(SERVER_CLOSED_CONNECTION_ERROR)
redis.exceptions.ConnectionError: Connection closed by server.
[2021-08-09 11:00:27,993: ERROR/MainProcess] consumer: Cannot connect to redis://localhost:6379/1: Error 111 connecting to localhost:6379. Connection refused..
Trying again in 2.00 seconds... (1/100)

[2021-08-09 11:00:30,000: INFO/MainProcess] Connected to redis://localhost:6379/1
[2021-08-09 11:00:30,015: INFO/MainProcess] mingle: searching for neighbors
[2021-08-09 11:00:31,023: INFO/MainProcess] mingle: all alone
[2021-08-09 11:00:34,694: WARNING/MainProcess] consumer: Connection to broker lost. Trying to re-establish the connection...
Traceback (most recent call last):
  File "/home/olcaey/koytola/venv/lib/python3.8/site-packages/celery/worker/consumer/consumer.py", line 318, in start
    blueprint.start(self)
  File "/home/olcaey/koytola/venv/lib/python3.8/site-packages/celery/bootsteps.py", line 119, in start
    step.start(parent)
  File "/home/olcaey/koytola/venv/lib/python3.8/site-packages/celery/worker/consumer/consumer.py", line 599, in start
    c.loop(*c.loop_args())
  File "/home/olcaey/koytola/venv/lib/python3.8/site-packages/celery/worker/loops.py", line 83, in asynloop
    next(loop)
  File "/home/olcaey/koytola/venv/lib/python3.8/site-packages/kombu/asynchronous/hub.py", line 364, in create_loop
    cb(*cbargs)
  File "/home/olcaey/koytola/venv/lib/python3.8/site-packages/kombu/transport/redis.py", line 1083, in on_readable
    self.cycle.on_readable(fileno)
  File "/home/olcaey/koytola/venv/lib/python3.8/site-packages/kombu/transport/redis.py", line 354, in on_readable
    chan.handlers[type]()
  File "/home/olcaey/koytola/venv/lib/python3.8/site-packages/kombu/transport/redis.py", line 688, in _receive
    ret.append(self._receive_one(c))
  File "/home/olcaey/koytola/venv/lib/python3.8/site-packages/kombu/transport/redis.py", line 698, in _receive_one
    response = c.parse_response()
  File "/home/olcaey/koytola/venv/lib/python3.8/site-packages/redis/client.py", line 3505, in parse_response
    response = self._execute(conn, conn.read_response)
  File "/home/olcaey/koytola/venv/lib/python3.8/site-packages/redis/client.py", line 3479, in _execute
    return command(*args, **kwargs)
  File "/home/olcaey/koytola/venv/lib/python3.8/site-packages/redis/connection.py", line 739, in read_response
    response = self._parser.read_response()
  File "/home/olcaey/koytola/venv/lib/python3.8/site-packages/redis/connection.py", line 324, in read_response
    raw = self._buffer.readline()
  File "/home/olcaey/koytola/venv/lib/python3.8/site-packages/redis/connection.py", line 256, in readline
    self._read_from_socket()
  File "/home/olcaey/koytola/venv/lib/python3.8/site-packages/redis/connection.py", line 201, in _read_from_socket
    raise ConnectionError(SERVER_CLOSED_CONNECTION_ERROR)
redis.exceptions.ConnectionError: Connection closed by server.
[2021-08-09 11:00:34,740: ERROR/MainProcess] consumer: Cannot connect to redis://localhost:6379/1: Error 111 connecting to localhost:6379. Connection refused..
Trying again in 2.00 seconds... (1/100)

[2021-08-09 11:00:36,746: INFO/MainProcess] Connected to redis://localhost:6379/1
[2021-08-09 11:00:36,763: INFO/MainProcess] mingle: searching for neighbors
[2021-08-09 11:00:37,773: INFO/MainProcess] mingle: all alone
[2021-08-09 11:55:46,203: INFO/MainProcess] Received task: koytola.account.emails._send_account_confirmation_email[eb81705d-e52e-4fbd-abb6-41b32f5549d7]  
/home/olcaey/koytola/venv/lib/python3.8/site-packages/graphene_django/types.py:94: UserWarning: Field name "description" doesn't exist on Django model "profile.Certificate". Consider removing the field from the "fields" list of DjangoObjectType "Certificate" because it has no effect.
  warnings.warn(
/home/olcaey/koytola/venv/lib/python3.8/site-packages/graphene_django/types.py:94: UserWarning: Field name "name" doesn't exist on Django model "profile.Certificate". Consider removing the field from the "fields" list of DjangoObjectType "Certificate" because it has no effect.
  warnings.warn(
/home/olcaey/koytola/venv/lib/python3.8/site-packages/graphene_django/types.py:94: UserWarning: Field name "content" doesn't exist on Django model "blog.Blog". Consider removing the field from the "fields" list of DjangoObjectType "BlogTranslatableContent" because it has no effect.
  warnings.warn(
/home/olcaey/koytola/venv/lib/python3.8/site-packages/graphene_django/types.py:94: UserWarning: Field name "summary" doesn't exist on Django model "blog.Blog". Consider removing the field from the "fields" list of DjangoObjectType "BlogTranslatableContent" because it has no effect.
  warnings.warn(
/home/olcaey/koytola/venv/lib/python3.8/site-packages/graphene_django/types.py:94: UserWarning: Field name "content_plaintext" doesn't exist on Django model "news.News". Consider removing the field from the "fields" list of DjangoObjectType "NewsTranslatableContent" because it has no effect.
  warnings.warn(
/home/olcaey/koytola/venv/lib/python3.8/site-packages/graphene_django/types.py:94: UserWarning: Field name "description" doesn't exist on Django model "news.News". Consider removing the field from the "fields" list of DjangoObjectType "News" because it has no effect.
  warnings.warn(
[2021-08-09 11:55:47,564: INFO/ForkPoolWorker-1] Task koytola.account.emails._send_account_confirmation_email[eb81705d-e52e-4fbd-abb6-41b32f5549d7] succeeded in 1.3462492427788675s: None
[2021-08-09 11:56:34,831: INFO/MainProcess] Received task: koytola.account.emails._send_account_confirmation_email[2ecc5a18-a928-430a-927c-386163eff3ec]  
[2021-08-09 11:56:35,774: INFO/ForkPoolWorker-1] Task koytola.account.emails._send_account_confirmation_email[2ecc5a18-a928-430a-927c-386163eff3ec] succeeded in 0.9419038323685527s: None
[2021-08-09 12:33:04,449: INFO/MainProcess] Received task: koytola.account.emails._send_account_confirmation_email[99785f25-9bc9-4371-bb0f-a0adf863499b]  
[2021-08-09 12:33:05,801: INFO/ForkPoolWorker-1] Task koytola.account.emails._send_account_confirmation_email[99785f25-9bc9-4371-bb0f-a0adf863499b] succeeded in 1.3503869720734656s: None
[2021-08-09 12:55:48,670: INFO/MainProcess] Received task: koytola.account.emails._send_account_confirmation_email[b0704878-b796-4c30-9174-48caf019d8b2]  
[2021-08-09 12:55:50,050: INFO/ForkPoolWorker-1] Task koytola.account.emails._send_account_confirmation_email[b0704878-b796-4c30-9174-48caf019d8b2] succeeded in 1.3784380010329187s: None
[2021-08-09 13:00:48,933: INFO/MainProcess] Received task: koytola.account.emails._send_account_confirmation_email[279009b0-444d-4a72-a46f-9484e08ba0f8]  
[2021-08-09 13:00:49,938: INFO/ForkPoolWorker-1] Task koytola.account.emails._send_account_confirmation_email[279009b0-444d-4a72-a46f-9484e08ba0f8] succeeded in 1.003512010909617s: None
/home/olcaey/koytola/venv/lib/python3.8/site-packages/graphene_django/types.py:94: UserWarning: Field name "description" doesn't exist on Django model "profile.Certificate". Consider removing the field from the "fields" list of DjangoObjectType "Certificate" because it has no effect.
  warnings.warn(
/home/olcaey/koytola/venv/lib/python3.8/site-packages/graphene_django/types.py:94: UserWarning: Field name "name" doesn't exist on Django model "profile.Certificate". Consider removing the field from the "fields" list of DjangoObjectType "Certificate" because it has no effect.
  warnings.warn(
/home/olcaey/koytola/venv/lib/python3.8/site-packages/graphene_django/types.py:94: UserWarning: Field name "content" doesn't exist on Django model "blog.Blog". Consider removing the field from the "fields" list of DjangoObjectType "BlogTranslatableContent" because it has no effect.
  warnings.warn(
/home/olcaey/koytola/venv/lib/python3.8/site-packages/graphene_django/types.py:94: UserWarning: Field name "summary" doesn't exist on Django model "blog.Blog". Consider removing the field from the "fields" list of DjangoObjectType "BlogTranslatableContent" because it has no effect.
  warnings.warn(
/home/olcaey/koytola/venv/lib/python3.8/site-packages/graphene_django/types.py:94: UserWarning: Field name "content_plaintext" doesn't exist on Django model "news.News". Consider removing the field from the "fields" list of DjangoObjectType "NewsTranslatableContent" because it has no effect.
  warnings.warn(
/home/olcaey/koytola/venv/lib/python3.8/site-packages/graphene_django/types.py:94: UserWarning: Field name "description" doesn't exist on Django model "news.News". Consider removing the field from the "fields" list of DjangoObjectType "News" because it has no effect.
  warnings.warn(
[2021-08-09 13:03:46,021: INFO/MainProcess] Connected to redis://localhost:6379/1
[2021-08-09 13:03:46,036: INFO/MainProcess] mingle: searching for neighbors
[2021-08-09 13:03:47,066: WARNING/MainProcess] /home/olcaey/koytola/venv/lib/python3.8/site-packages/celery/app/control.py:52: DuplicateNodenameWarning: Received multiple replies from node name: celery@koytola-dev.
Please make sure you give each node a unique nodename using
the celery worker `-n` option.
  warnings.warn(DuplicateNodenameWarning(
[2021-08-09 13:03:47,067: INFO/MainProcess] mingle: all alone
[2021-08-09 13:03:47,082: INFO/MainProcess] celery@koytola-dev ready.
[2021-08-09 13:08:06,686: WARNING/MainProcess] consumer: Connection to broker lost. Trying to re-establish the connection...
Traceback (most recent call last):
  File "/home/olcaey/koytola/venv/lib/python3.8/site-packages/celery/worker/consumer/consumer.py", line 318, in start
    blueprint.start(self)
  File "/home/olcaey/koytola/venv/lib/python3.8/site-packages/celery/bootsteps.py", line 119, in start
    step.start(parent)
  File "/home/olcaey/koytola/venv/lib/python3.8/site-packages/celery/worker/consumer/consumer.py", line 599, in start
    c.loop(*c.loop_args())
  File "/home/olcaey/koytola/venv/lib/python3.8/site-packages/celery/worker/loops.py", line 83, in asynloop
    next(loop)
  File "/home/olcaey/koytola/venv/lib/python3.8/site-packages/kombu/asynchronous/hub.py", line 364, in create_loop
    cb(*cbargs)
  File "/home/olcaey/koytola/venv/lib/python3.8/site-packages/kombu/transport/redis.py", line 1083, in on_readable
    self.cycle.on_readable(fileno)
  File "/home/olcaey/koytola/venv/lib/python3.8/site-packages/kombu/transport/redis.py", line 354, in on_readable
    chan.handlers[type]()
  File "/home/olcaey/koytola/venv/lib/python3.8/site-packages/kombu/transport/redis.py", line 688, in _receive
    ret.append(self._receive_one(c))
  File "/home/olcaey/koytola/venv/lib/python3.8/site-packages/kombu/transport/redis.py", line 698, in _receive_one
    response = c.parse_response()
  File "/home/olcaey/koytola/venv/lib/python3.8/site-packages/redis/client.py", line 3505, in parse_response
    response = self._execute(conn, conn.read_response)
  File "/home/olcaey/koytola/venv/lib/python3.8/site-packages/redis/client.py", line 3479, in _execute
    return command(*args, **kwargs)
  File "/home/olcaey/koytola/venv/lib/python3.8/site-packages/redis/connection.py", line 739, in read_response
    response = self._parser.read_response()
  File "/home/olcaey/koytola/venv/lib/python3.8/site-packages/redis/connection.py", line 324, in read_response
    raw = self._buffer.readline()
  File "/home/olcaey/koytola/venv/lib/python3.8/site-packages/redis/connection.py", line 256, in readline
    self._read_from_socket()
  File "/home/olcaey/koytola/venv/lib/python3.8/site-packages/redis/connection.py", line 201, in _read_from_socket
    raise ConnectionError(SERVER_CLOSED_CONNECTION_ERROR)
redis.exceptions.ConnectionError: Connection closed by server.
[2021-08-09 13:08:06,732: ERROR/MainProcess] consumer: Cannot connect to redis://localhost:6379/1: Error 111 connecting to localhost:6379. Connection refused..
Trying again in 2.00 seconds... (1/100)

[2021-08-09 13:08:08,738: INFO/MainProcess] Connected to redis://localhost:6379/1
[2021-08-09 13:08:08,754: INFO/MainProcess] mingle: searching for neighbors
[2021-08-09 13:08:09,762: INFO/MainProcess] mingle: all alone
[2021-08-09 22:47:18,615: INFO/MainProcess] Received task: koytola.account.emails._send_password_reset_email_with_url[e1890ed2-a593-4281-911b-b8f88320da48]  
/home/olcaey/koytola/venv/lib/python3.8/site-packages/graphene_django/types.py:94: UserWarning: Field name "description" doesn't exist on Django model "profile.Certificate". Consider removing the field from the "fields" list of DjangoObjectType "Certificate" because it has no effect.
  warnings.warn(
/home/olcaey/koytola/venv/lib/python3.8/site-packages/graphene_django/types.py:94: UserWarning: Field name "name" doesn't exist on Django model "profile.Certificate". Consider removing the field from the "fields" list of DjangoObjectType "Certificate" because it has no effect.
  warnings.warn(
/home/olcaey/koytola/venv/lib/python3.8/site-packages/graphene_django/types.py:94: UserWarning: Field name "content" doesn't exist on Django model "blog.Blog". Consider removing the field from the "fields" list of DjangoObjectType "BlogTranslatableContent" because it has no effect.
  warnings.warn(
/home/olcaey/koytola/venv/lib/python3.8/site-packages/graphene_django/types.py:94: UserWarning: Field name "summary" doesn't exist on Django model "blog.Blog". Consider removing the field from the "fields" list of DjangoObjectType "BlogTranslatableContent" because it has no effect.
  warnings.warn(
/home/olcaey/koytola/venv/lib/python3.8/site-packages/graphene_django/types.py:94: UserWarning: Field name "content_plaintext" doesn't exist on Django model "news.News". Consider removing the field from the "fields" list of DjangoObjectType "NewsTranslatableContent" because it has no effect.
  warnings.warn(
/home/olcaey/koytola/venv/lib/python3.8/site-packages/graphene_django/types.py:94: UserWarning: Field name "description" doesn't exist on Django model "news.News". Consider removing the field from the "fields" list of DjangoObjectType "News" because it has no effect.
  warnings.warn(
[2021-08-09 22:47:20,600: INFO/ForkPoolWorker-1] Task koytola.account.emails._send_password_reset_email_with_url[e1890ed2-a593-4281-911b-b8f88320da48] succeeded in 1.967104913201183s: None
[2021-08-10 11:52:50,335: INFO/MainProcess] Received task: koytola.account.emails._send_password_reset_email_with_url[4d07f715-4646-459f-a383-50b986080b09]  
[2021-08-10 11:52:52,093: INFO/ForkPoolWorker-1] Task koytola.account.emails._send_password_reset_email_with_url[4d07f715-4646-459f-a383-50b986080b09] succeeded in 1.7383379088714719s: None
/home/olcaey/koytola/venv/lib/python3.8/site-packages/graphene_django/types.py:94: UserWarning: Field name "description" doesn't exist on Django model "profile.Certificate". Consider removing the field from the "fields" list of DjangoObjectType "Certificate" because it has no effect.
  warnings.warn(
/home/olcaey/koytola/venv/lib/python3.8/site-packages/graphene_django/types.py:94: UserWarning: Field name "name" doesn't exist on Django model "profile.Certificate". Consider removing the field from the "fields" list of DjangoObjectType "Certificate" because it has no effect.
  warnings.warn(
/home/olcaey/koytola/venv/lib/python3.8/site-packages/graphene_django/types.py:94: UserWarning: Field name "content" doesn't exist on Django model "blog.Blog". Consider removing the field from the "fields" list of DjangoObjectType "BlogTranslatableContent" because it has no effect.
  warnings.warn(
/home/olcaey/koytola/venv/lib/python3.8/site-packages/graphene_django/types.py:94: UserWarning: Field name "summary" doesn't exist on Django model "blog.Blog". Consider removing the field from the "fields" list of DjangoObjectType "BlogTranslatableContent" because it has no effect.
  warnings.warn(
/home/olcaey/koytola/venv/lib/python3.8/site-packages/graphene_django/types.py:94: UserWarning: Field name "content_plaintext" doesn't exist on Django model "news.News". Consider removing the field from the "fields" list of DjangoObjectType "NewsTranslatableContent" because it has no effect.
  warnings.warn(
/home/olcaey/koytola/venv/lib/python3.8/site-packages/graphene_django/types.py:94: UserWarning: Field name "description" doesn't exist on Django model "news.News". Consider removing the field from the "fields" list of DjangoObjectType "News" because it has no effect.
  warnings.warn(
[2021-08-12 04:26:59,695: INFO/MainProcess] Connected to redis://localhost:6379/1
[2021-08-12 04:26:59,706: INFO/MainProcess] mingle: searching for neighbors
[2021-08-12 04:27:00,748: WARNING/MainProcess] /home/olcaey/koytola/venv/lib/python3.8/site-packages/celery/app/control.py:52: DuplicateNodenameWarning: Received multiple replies from node name: celery@koytola-dev.
Please make sure you give each node a unique nodename using
the celery worker `-n` option.
  warnings.warn(DuplicateNodenameWarning(
[2021-08-12 04:27:00,748: INFO/MainProcess] mingle: all alone
[2021-08-12 04:27:00,765: INFO/MainProcess] celery@koytola-dev ready.
[2021-08-12 04:27:27,938: INFO/MainProcess] Received task: koytola.account.emails._send_account_confirmation_email[b8f9aebe-0c7e-4fa4-a38e-0f0049f9510a]  
/home/olcaey/koytola/venv/lib/python3.8/site-packages/graphene_django/types.py:94: UserWarning: Field name "description" doesn't exist on Django model "profile.Certificate". Consider removing the field from the "fields" list of DjangoObjectType "Certificate" because it has no effect.
  warnings.warn(
/home/olcaey/koytola/venv/lib/python3.8/site-packages/graphene_django/types.py:94: UserWarning: Field name "name" doesn't exist on Django model "profile.Certificate". Consider removing the field from the "fields" list of DjangoObjectType "Certificate" because it has no effect.
  warnings.warn(
/home/olcaey/koytola/venv/lib/python3.8/site-packages/graphene_django/types.py:94: UserWarning: Field name "content" doesn't exist on Django model "blog.Blog". Consider removing the field from the "fields" list of DjangoObjectType "BlogTranslatableContent" because it has no effect.
  warnings.warn(
/home/olcaey/koytola/venv/lib/python3.8/site-packages/graphene_django/types.py:94: UserWarning: Field name "summary" doesn't exist on Django model "blog.Blog". Consider removing the field from the "fields" list of DjangoObjectType "BlogTranslatableContent" because it has no effect.
  warnings.warn(
/home/olcaey/koytola/venv/lib/python3.8/site-packages/graphene_django/types.py:94: UserWarning: Field name "content_plaintext" doesn't exist on Django model "news.News". Consider removing the field from the "fields" list of DjangoObjectType "NewsTranslatableContent" because it has no effect.
  warnings.warn(
/home/olcaey/koytola/venv/lib/python3.8/site-packages/graphene_django/types.py:94: UserWarning: Field name "description" doesn't exist on Django model "news.News". Consider removing the field from the "fields" list of DjangoObjectType "News" because it has no effect.
  warnings.warn(
[2021-08-12 04:27:29,609: INFO/ForkPoolWorker-1] Task koytola.account.emails._send_account_confirmation_email[b8f9aebe-0c7e-4fa4-a38e-0f0049f9510a] succeeded in 1.6687041521072388s: None
[2021-08-12 05:01:15,678: INFO/MainProcess] Received task: koytola.account.emails._send_account_confirmation_email[c2d04615-10d1-49ee-b7da-098c1cc42e3a]  
[2021-08-12 05:01:17,254: INFO/ForkPoolWorker-1] Task koytola.account.emails._send_account_confirmation_email[c2d04615-10d1-49ee-b7da-098c1cc42e3a] succeeded in 1.550840319134295s: None
/home/olcaey/koytola/venv/lib/python3.8/site-packages/graphene_django/types.py:94: UserWarning: Field name "description" doesn't exist on Django model "profile.Certificate". Consider removing the field from the "fields" list of DjangoObjectType "Certificate" because it has no effect.
  warnings.warn(
/home/olcaey/koytola/venv/lib/python3.8/site-packages/graphene_django/types.py:94: UserWarning: Field name "name" doesn't exist on Django model "profile.Certificate". Consider removing the field from the "fields" list of DjangoObjectType "Certificate" because it has no effect.
  warnings.warn(
/home/olcaey/koytola/venv/lib/python3.8/site-packages/graphene_django/types.py:94: UserWarning: Field name "content" doesn't exist on Django model "blog.Blog". Consider removing the field from the "fields" list of DjangoObjectType "BlogTranslatableContent" because it has no effect.
  warnings.warn(
/home/olcaey/koytola/venv/lib/python3.8/site-packages/graphene_django/types.py:94: UserWarning: Field name "summary" doesn't exist on Django model "blog.Blog". Consider removing the field from the "fields" list of DjangoObjectType "BlogTranslatableContent" because it has no effect.
  warnings.warn(
/home/olcaey/koytola/venv/lib/python3.8/site-packages/graphene_django/types.py:94: UserWarning: Field name "content_plaintext" doesn't exist on Django model "news.News". Consider removing the field from the "fields" list of DjangoObjectType "NewsTranslatableContent" because it has no effect.
  warnings.warn(
/home/olcaey/koytola/venv/lib/python3.8/site-packages/graphene_django/types.py:94: UserWarning: Field name "description" doesn't exist on Django model "news.News". Consider removing the field from the "fields" list of DjangoObjectType "News" because it has no effect.
  warnings.warn(
[2021-08-12 05:02:34,610: INFO/MainProcess] Connected to redis://localhost:6379/1
[2021-08-12 05:02:34,623: INFO/MainProcess] mingle: searching for neighbors
[2021-08-12 05:02:35,655: WARNING/MainProcess] /home/olcaey/koytola/venv/lib/python3.8/site-packages/celery/app/control.py:52: DuplicateNodenameWarning: Received multiple replies from node name: celery@koytola-dev.
Please make sure you give each node a unique nodename using
the celery worker `-n` option.
  warnings.warn(DuplicateNodenameWarning(
[2021-08-12 05:02:35,655: INFO/MainProcess] mingle: all alone
[2021-08-12 05:02:35,667: INFO/MainProcess] celery@koytola-dev ready.
/home/olcaey/koytola/venv/lib/python3.8/site-packages/graphene_django/types.py:94: UserWarning: Field name "description" doesn't exist on Django model "profile.Certificate". Consider removing the field from the "fields" list of DjangoObjectType "Certificate" because it has no effect.
  warnings.warn(
/home/olcaey/koytola/venv/lib/python3.8/site-packages/graphene_django/types.py:94: UserWarning: Field name "name" doesn't exist on Django model "profile.Certificate". Consider removing the field from the "fields" list of DjangoObjectType "Certificate" because it has no effect.
  warnings.warn(
/home/olcaey/koytola/venv/lib/python3.8/site-packages/graphene_django/types.py:94: UserWarning: Field name "content" doesn't exist on Django model "blog.Blog". Consider removing the field from the "fields" list of DjangoObjectType "BlogTranslatableContent" because it has no effect.
  warnings.warn(
/home/olcaey/koytola/venv/lib/python3.8/site-packages/graphene_django/types.py:94: UserWarning: Field name "summary" doesn't exist on Django model "blog.Blog". Consider removing the field from the "fields" list of DjangoObjectType "BlogTranslatableContent" because it has no effect.
  warnings.warn(
/home/olcaey/koytola/venv/lib/python3.8/site-packages/graphene_django/types.py:94: UserWarning: Field name "content_plaintext" doesn't exist on Django model "news.News". Consider removing the field from the "fields" list of DjangoObjectType "NewsTranslatableContent" because it has no effect.
  warnings.warn(
/home/olcaey/koytola/venv/lib/python3.8/site-packages/graphene_django/types.py:94: UserWarning: Field name "description" doesn't exist on Django model "news.News". Consider removing the field from the "fields" list of DjangoObjectType "News" because it has no effect.
  warnings.warn(
[2021-08-12 05:02:52,995: INFO/MainProcess] Connected to redis://localhost:6379/1
[2021-08-12 05:02:53,005: INFO/MainProcess] mingle: searching for neighbors
[2021-08-12 05:02:54,036: WARNING/MainProcess] /home/olcaey/koytola/venv/lib/python3.8/site-packages/celery/app/control.py:52: DuplicateNodenameWarning: Received multiple replies from node name: celery@koytola-dev.
Please make sure you give each node a unique nodename using
the celery worker `-n` option.
  warnings.warn(DuplicateNodenameWarning(
[2021-08-12 05:02:54,036: INFO/MainProcess] mingle: all alone
[2021-08-12 05:02:54,065: INFO/MainProcess] celery@koytola-dev ready.
[2021-08-12 05:03:10,714: INFO/MainProcess] Received task: koytola.account.emails._send_account_confirmation_email[da1ac7f5-dbad-4c21-afbd-3b0ac4cf5d6c]  
[2021-08-12 05:03:11,633: INFO/ForkPoolWorker-1] Task koytola.account.emails._send_account_confirmation_email[da1ac7f5-dbad-4c21-afbd-3b0ac4cf5d6c] succeeded in 0.9174977308139205s: None
[2021-08-12 05:04:30,374: INFO/MainProcess] Received task: koytola.account.emails._send_account_confirmation_email[73766723-205d-45f5-9569-b40c69d9a144]  
/home/olcaey/koytola/venv/lib/python3.8/site-packages/graphene_django/types.py:94: UserWarning: Field name "description" doesn't exist on Django model "profile.Certificate". Consider removing the field from the "fields" list of DjangoObjectType "Certificate" because it has no effect.
  warnings.warn(
/home/olcaey/koytola/venv/lib/python3.8/site-packages/graphene_django/types.py:94: UserWarning: Field name "name" doesn't exist on Django model "profile.Certificate". Consider removing the field from the "fields" list of DjangoObjectType "Certificate" because it has no effect.
  warnings.warn(
/home/olcaey/koytola/venv/lib/python3.8/site-packages/graphene_django/types.py:94: UserWarning: Field name "content" doesn't exist on Django model "blog.Blog". Consider removing the field from the "fields" list of DjangoObjectType "BlogTranslatableContent" because it has no effect.
  warnings.warn(
/home/olcaey/koytola/venv/lib/python3.8/site-packages/graphene_django/types.py:94: UserWarning: Field name "summary" doesn't exist on Django model "blog.Blog". Consider removing the field from the "fields" list of DjangoObjectType "BlogTranslatableContent" because it has no effect.
  warnings.warn(
/home/olcaey/koytola/venv/lib/python3.8/site-packages/graphene_django/types.py:94: UserWarning: Field name "content_plaintext" doesn't exist on Django model "news.News". Consider removing the field from the "fields" list of DjangoObjectType "NewsTranslatableContent" because it has no effect.
  warnings.warn(
/home/olcaey/koytola/venv/lib/python3.8/site-packages/graphene_django/types.py:94: UserWarning: Field name "description" doesn't exist on Django model "news.News". Consider removing the field from the "fields" list of DjangoObjectType "News" because it has no effect.
  warnings.warn(
[2021-08-12 05:04:31,441: INFO/ForkPoolWorker-1] Task koytola.account.emails._send_account_confirmation_email[73766723-205d-45f5-9569-b40c69d9a144] succeeded in 1.0641790190711617s: None
/home/olcaey/koytola/venv/lib/python3.8/site-packages/graphene_django/types.py:94: UserWarning: Field name "description" doesn't exist on Django model "profile.Certificate". Consider removing the field from the "fields" list of DjangoObjectType "Certificate" because it has no effect.
  warnings.warn(
/home/olcaey/koytola/venv/lib/python3.8/site-packages/graphene_django/types.py:94: UserWarning: Field name "name" doesn't exist on Django model "profile.Certificate". Consider removing the field from the "fields" list of DjangoObjectType "Certificate" because it has no effect.
  warnings.warn(
/home/olcaey/koytola/venv/lib/python3.8/site-packages/graphene_django/types.py:94: UserWarning: Field name "content" doesn't exist on Django model "blog.Blog". Consider removing the field from the "fields" list of DjangoObjectType "BlogTranslatableContent" because it has no effect.
  warnings.warn(
/home/olcaey/koytola/venv/lib/python3.8/site-packages/graphene_django/types.py:94: UserWarning: Field name "summary" doesn't exist on Django model "blog.Blog". Consider removing the field from the "fields" list of DjangoObjectType "BlogTranslatableContent" because it has no effect.
  warnings.warn(
/home/olcaey/koytola/venv/lib/python3.8/site-packages/graphene_django/types.py:94: UserWarning: Field name "content_plaintext" doesn't exist on Django model "news.News". Consider removing the field from the "fields" list of DjangoObjectType "NewsTranslatableContent" because it has no effect.
  warnings.warn(
/home/olcaey/koytola/venv/lib/python3.8/site-packages/graphene_django/types.py:94: UserWarning: Field name "description" doesn't exist on Django model "news.News". Consider removing the field from the "fields" list of DjangoObjectType "News" because it has no effect.
  warnings.warn(
[2021-08-12 05:05:34,434: INFO/MainProcess] Connected to redis://localhost:6379/1
[2021-08-12 05:05:34,442: INFO/MainProcess] mingle: searching for neighbors
[2021-08-12 05:05:35,472: WARNING/MainProcess] /home/olcaey/koytola/venv/lib/python3.8/site-packages/celery/app/control.py:52: DuplicateNodenameWarning: Received multiple replies from node name: celery@koytola-dev.
Please make sure you give each node a unique nodename using
the celery worker `-n` option.
  warnings.warn(DuplicateNodenameWarning(
[2021-08-12 05:05:35,472: INFO/MainProcess] mingle: all alone
[2021-08-12 05:05:35,486: INFO/MainProcess] celery@koytola-dev ready.
[2021-08-12 05:05:48,256: INFO/MainProcess] Received task: koytola.account.emails._send_account_confirmation_email[03bcde0b-b59a-4321-84d7-48c933f79e29]  
/home/olcaey/koytola/venv/lib/python3.8/site-packages/graphene_django/types.py:94: UserWarning: Field name "description" doesn't exist on Django model "profile.Certificate". Consider removing the field from the "fields" list of DjangoObjectType "Certificate" because it has no effect.
  warnings.warn(
/home/olcaey/koytola/venv/lib/python3.8/site-packages/graphene_django/types.py:94: UserWarning: Field name "name" doesn't exist on Django model "profile.Certificate". Consider removing the field from the "fields" list of DjangoObjectType "Certificate" because it has no effect.
  warnings.warn(
/home/olcaey/koytola/venv/lib/python3.8/site-packages/graphene_django/types.py:94: UserWarning: Field name "content" doesn't exist on Django model "blog.Blog". Consider removing the field from the "fields" list of DjangoObjectType "BlogTranslatableContent" because it has no effect.
  warnings.warn(
/home/olcaey/koytola/venv/lib/python3.8/site-packages/graphene_django/types.py:94: UserWarning: Field name "summary" doesn't exist on Django model "blog.Blog". Consider removing the field from the "fields" list of DjangoObjectType "BlogTranslatableContent" because it has no effect.
  warnings.warn(
/home/olcaey/koytola/venv/lib/python3.8/site-packages/graphene_django/types.py:94: UserWarning: Field name "content_plaintext" doesn't exist on Django model "news.News". Consider removing the field from the "fields" list of DjangoObjectType "NewsTranslatableContent" because it has no effect.
  warnings.warn(
/home/olcaey/koytola/venv/lib/python3.8/site-packages/graphene_django/types.py:94: UserWarning: Field name "description" doesn't exist on Django model "news.News". Consider removing the field from the "fields" list of DjangoObjectType "News" because it has no effect.
  warnings.warn(
[2021-08-12 05:05:49,299: INFO/ForkPoolWorker-1] Task koytola.account.emails._send_account_confirmation_email[03bcde0b-b59a-4321-84d7-48c933f79e29] succeeded in 1.0404968787916005s: None
[2021-08-12 05:11:34,278: INFO/MainProcess] Received task: koytola.account.emails._send_account_confirmation_email[20de0117-1d85-4992-b821-aa0ac7bb2cb2]  
[2021-08-12 05:11:35,299: INFO/ForkPoolWorker-1] Task koytola.account.emails._send_account_confirmation_email[20de0117-1d85-4992-b821-aa0ac7bb2cb2] succeeded in 1.0200087600387633s: None
[2021-08-12 05:19:58,528: INFO/MainProcess] Received task: koytola.account.emails._send_account_confirmation_email[ee29d84e-a346-4b87-8a2e-68c57ef8d603]  
[2021-08-12 05:19:59,533: INFO/ForkPoolWorker-1] Task koytola.account.emails._send_account_confirmation_email[ee29d84e-a346-4b87-8a2e-68c57ef8d603] succeeded in 1.003904063720256s: None
[2021-08-12 05:21:40,232: INFO/MainProcess] Received task: koytola.account.emails._send_account_confirmation_email[7cd16001-01a6-4fd6-afea-d0fb05b3d35d]  
[2021-08-12 05:21:41,229: INFO/ForkPoolWorker-1] Task koytola.account.emails._send_account_confirmation_email[7cd16001-01a6-4fd6-afea-d0fb05b3d35d] succeeded in 0.9960164236836135s: None
[2021-08-12 06:56:41,107: WARNING/MainProcess] consumer: Connection to broker lost. Trying to re-establish the connection...
Traceback (most recent call last):
  File "/home/olcaey/koytola/venv/lib/python3.8/site-packages/celery/worker/consumer/consumer.py", line 318, in start
    blueprint.start(self)
  File "/home/olcaey/koytola/venv/lib/python3.8/site-packages/celery/bootsteps.py", line 119, in start
    step.start(parent)
  File "/home/olcaey/koytola/venv/lib/python3.8/site-packages/celery/worker/consumer/consumer.py", line 599, in start
    c.loop(*c.loop_args())
  File "/home/olcaey/koytola/venv/lib/python3.8/site-packages/celery/worker/loops.py", line 83, in asynloop
    next(loop)
  File "/home/olcaey/koytola/venv/lib/python3.8/site-packages/kombu/asynchronous/hub.py", line 364, in create_loop
    cb(*cbargs)
  File "/home/olcaey/koytola/venv/lib/python3.8/site-packages/kombu/transport/redis.py", line 1083, in on_readable
    self.cycle.on_readable(fileno)
  File "/home/olcaey/koytola/venv/lib/python3.8/site-packages/kombu/transport/redis.py", line 354, in on_readable
    chan.handlers[type]()
  File "/home/olcaey/koytola/venv/lib/python3.8/site-packages/kombu/transport/redis.py", line 688, in _receive
    ret.append(self._receive_one(c))
  File "/home/olcaey/koytola/venv/lib/python3.8/site-packages/kombu/transport/redis.py", line 698, in _receive_one
    response = c.parse_response()
  File "/home/olcaey/koytola/venv/lib/python3.8/site-packages/redis/client.py", line 3505, in parse_response
    response = self._execute(conn, conn.read_response)
  File "/home/olcaey/koytola/venv/lib/python3.8/site-packages/redis/client.py", line 3479, in _execute
    return command(*args, **kwargs)
  File "/home/olcaey/koytola/venv/lib/python3.8/site-packages/redis/connection.py", line 739, in read_response
    response = self._parser.read_response()
  File "/home/olcaey/koytola/venv/lib/python3.8/site-packages/redis/connection.py", line 324, in read_response
    raw = self._buffer.readline()
  File "/home/olcaey/koytola/venv/lib/python3.8/site-packages/redis/connection.py", line 256, in readline
    self._read_from_socket()
  File "/home/olcaey/koytola/venv/lib/python3.8/site-packages/redis/connection.py", line 201, in _read_from_socket
    raise ConnectionError(SERVER_CLOSED_CONNECTION_ERROR)
redis.exceptions.ConnectionError: Connection closed by server.
[2021-08-12 06:56:41,085: WARNING/MainProcess] consumer: Connection to broker lost. Trying to re-establish the connection...
Traceback (most recent call last):
  File "/home/olcaey/koytola/venv/lib/python3.8/site-packages/celery/worker/consumer/consumer.py", line 318, in start
    blueprint.start(self)
  File "/home/olcaey/koytola/venv/lib/python3.8/site-packages/celery/bootsteps.py", line 119, in start
    step.start(parent)
  File "/home/olcaey/koytola/venv/lib/python3.8/site-packages/celery/worker/consumer/consumer.py", line 599, in start
    c.loop(*c.loop_args())
  File "/home/olcaey/koytola/venv/lib/python3.8/site-packages/celery/worker/loops.py", line 83, in asynloop
    next(loop)
  File "/home/olcaey/koytola/venv/lib/python3.8/site-packages/kombu/asynchronous/hub.py", line 364, in create_loop
    cb(*cbargs)
  File "/home/olcaey/koytola/venv/lib/python3.8/site-packages/kombu/transport/redis.py", line 1083, in on_readable
    self.cycle.on_readable(fileno)
  File "/home/olcaey/koytola/venv/lib/python3.8/site-packages/kombu/transport/redis.py", line 354, in on_readable
    chan.handlers[type]()
  File "/home/olcaey/koytola/venv/lib/python3.8/site-packages/kombu/transport/redis.py", line 688, in _receive
    ret.append(self._receive_one(c))
  File "/home/olcaey/koytola/venv/lib/python3.8/site-packages/kombu/transport/redis.py", line 698, in _receive_one
    response = c.parse_response()
  File "/home/olcaey/koytola/venv/lib/python3.8/site-packages/redis/client.py", line 3505, in parse_response
    response = self._execute(conn, conn.read_response)
  File "/home/olcaey/koytola/venv/lib/python3.8/site-packages/redis/client.py", line 3479, in _execute
    return command(*args, **kwargs)
  File "/home/olcaey/koytola/venv/lib/python3.8/site-packages/redis/connection.py", line 739, in read_response
    response = self._parser.read_response()
  File "/home/olcaey/koytola/venv/lib/python3.8/site-packages/redis/connection.py", line 324, in read_response
    raw = self._buffer.readline()
  File "/home/olcaey/koytola/venv/lib/python3.8/site-packages/redis/connection.py", line 256, in readline
    self._read_from_socket()
  File "/home/olcaey/koytola/venv/lib/python3.8/site-packages/redis/connection.py", line 201, in _read_from_socket
    raise ConnectionError(SERVER_CLOSED_CONNECTION_ERROR)
redis.exceptions.ConnectionError: Connection closed by server.
[2021-08-12 06:56:41,083: WARNING/MainProcess] consumer: Connection to broker lost. Trying to re-establish the connection...
Traceback (most recent call last):
  File "/home/olcaey/koytola/venv/lib/python3.8/site-packages/celery/worker/consumer/consumer.py", line 318, in start
    blueprint.start(self)
  File "/home/olcaey/koytola/venv/lib/python3.8/site-packages/celery/bootsteps.py", line 119, in start
    step.start(parent)
  File "/home/olcaey/koytola/venv/lib/python3.8/site-packages/celery/worker/consumer/consumer.py", line 599, in start
    c.loop(*c.loop_args())
  File "/home/olcaey/koytola/venv/lib/python3.8/site-packages/celery/worker/loops.py", line 83, in asynloop
    next(loop)
  File "/home/olcaey/koytola/venv/lib/python3.8/site-packages/kombu/asynchronous/hub.py", line 364, in create_loop
    cb(*cbargs)
  File "/home/olcaey/koytola/venv/lib/python3.8/site-packages/kombu/transport/redis.py", line 1083, in on_readable
    self.cycle.on_readable(fileno)
  File "/home/olcaey/koytola/venv/lib/python3.8/site-packages/kombu/transport/redis.py", line 354, in on_readable
    chan.handlers[type]()
  File "/home/olcaey/koytola/venv/lib/python3.8/site-packages/kombu/transport/redis.py", line 688, in _receive
    ret.append(self._receive_one(c))
  File "/home/olcaey/koytola/venv/lib/python3.8/site-packages/kombu/transport/redis.py", line 698, in _receive_one
    response = c.parse_response()
  File "/home/olcaey/koytola/venv/lib/python3.8/site-packages/redis/client.py", line 3505, in parse_response
    response = self._execute(conn, conn.read_response)
  File "/home/olcaey/koytola/venv/lib/python3.8/site-packages/redis/client.py", line 3479, in _execute
    return command(*args, **kwargs)
  File "/home/olcaey/koytola/venv/lib/python3.8/site-packages/redis/connection.py", line 739, in read_response
    response = self._parser.read_response()
  File "/home/olcaey/koytola/venv/lib/python3.8/site-packages/redis/connection.py", line 324, in read_response
    raw = self._buffer.readline()
  File "/home/olcaey/koytola/venv/lib/python3.8/site-packages/redis/connection.py", line 256, in readline
    self._read_from_socket()
  File "/home/olcaey/koytola/venv/lib/python3.8/site-packages/redis/connection.py", line 201, in _read_from_socket
    raise ConnectionError(SERVER_CLOSED_CONNECTION_ERROR)
redis.exceptions.ConnectionError: Connection closed by server.
[2021-08-12 06:56:41,103: WARNING/MainProcess] consumer: Connection to broker lost. Trying to re-establish the connection...
Traceback (most recent call last):
  File "/home/olcaey/koytola/venv/lib/python3.8/site-packages/celery/worker/consumer/consumer.py", line 318, in start
    blueprint.start(self)
  File "/home/olcaey/koytola/venv/lib/python3.8/site-packages/celery/bootsteps.py", line 119, in start
    step.start(parent)
  File "/home/olcaey/koytola/venv/lib/python3.8/site-packages/celery/worker/consumer/consumer.py", line 599, in start
    c.loop(*c.loop_args())
  File "/home/olcaey/koytola/venv/lib/python3.8/site-packages/celery/worker/loops.py", line 83, in asynloop
    next(loop)
  File "/home/olcaey/koytola/venv/lib/python3.8/site-packages/kombu/asynchronous/hub.py", line 364, in create_loop
    cb(*cbargs)
  File "/home/olcaey/koytola/venv/lib/python3.8/site-packages/kombu/transport/redis.py", line 1083, in on_readable
    self.cycle.on_readable(fileno)
  File "/home/olcaey/koytola/venv/lib/python3.8/site-packages/kombu/transport/redis.py", line 354, in on_readable
    chan.handlers[type]()
  File "/home/olcaey/koytola/venv/lib/python3.8/site-packages/kombu/transport/redis.py", line 688, in _receive
    ret.append(self._receive_one(c))
  File "/home/olcaey/koytola/venv/lib/python3.8/site-packages/kombu/transport/redis.py", line 698, in _receive_one
    response = c.parse_response()
  File "/home/olcaey/koytola/venv/lib/python3.8/site-packages/redis/client.py", line 3505, in parse_response
    response = self._execute(conn, conn.read_response)
  File "/home/olcaey/koytola/venv/lib/python3.8/site-packages/redis/client.py", line 3479, in _execute
    return command(*args, **kwargs)
  File "/home/olcaey/koytola/venv/lib/python3.8/site-packages/redis/connection.py", line 739, in read_response
    response = self._parser.read_response()
  File "/home/olcaey/koytola/venv/lib/python3.8/site-packages/redis/connection.py", line 324, in read_response
    raw = self._buffer.readline()
  File "/home/olcaey/koytola/venv/lib/python3.8/site-packages/redis/connection.py", line 256, in readline
    self._read_from_socket()
  File "/home/olcaey/koytola/venv/lib/python3.8/site-packages/redis/connection.py", line 201, in _read_from_socket
    raise ConnectionError(SERVER_CLOSED_CONNECTION_ERROR)
redis.exceptions.ConnectionError: Connection closed by server.
[2021-08-12 06:56:41,119: WARNING/MainProcess] consumer: Connection to broker lost. Trying to re-establish the connection...
Traceback (most recent call last):
  File "/home/olcaey/koytola/venv/lib/python3.8/site-packages/celery/worker/consumer/consumer.py", line 318, in start
    blueprint.start(self)
  File "/home/olcaey/koytola/venv/lib/python3.8/site-packages/celery/bootsteps.py", line 119, in start
    step.start(parent)
  File "/home/olcaey/koytola/venv/lib/python3.8/site-packages/celery/worker/consumer/consumer.py", line 599, in start
    c.loop(*c.loop_args())
  File "/home/olcaey/koytola/venv/lib/python3.8/site-packages/celery/worker/loops.py", line 83, in asynloop
    next(loop)
  File "/home/olcaey/koytola/venv/lib/python3.8/site-packages/kombu/asynchronous/hub.py", line 364, in create_loop
    cb(*cbargs)
  File "/home/olcaey/koytola/venv/lib/python3.8/site-packages/kombu/transport/redis.py", line 1083, in on_readable
    self.cycle.on_readable(fileno)
  File "/home/olcaey/koytola/venv/lib/python3.8/site-packages/kombu/transport/redis.py", line 354, in on_readable
    chan.handlers[type]()
  File "/home/olcaey/koytola/venv/lib/python3.8/site-packages/kombu/transport/redis.py", line 688, in _receive
    ret.append(self._receive_one(c))
  File "/home/olcaey/koytola/venv/lib/python3.8/site-packages/kombu/transport/redis.py", line 698, in _receive_one
    response = c.parse_response()
  File "/home/olcaey/koytola/venv/lib/python3.8/site-packages/redis/client.py", line 3505, in parse_response
    response = self._execute(conn, conn.read_response)
  File "/home/olcaey/koytola/venv/lib/python3.8/site-packages/redis/client.py", line 3479, in _execute
    return command(*args, **kwargs)
  File "/home/olcaey/koytola/venv/lib/python3.8/site-packages/redis/connection.py", line 739, in read_response
    response = self._parser.read_response()
  File "/home/olcaey/koytola/venv/lib/python3.8/site-packages/redis/connection.py", line 324, in read_response
    raw = self._buffer.readline()
  File "/home/olcaey/koytola/venv/lib/python3.8/site-packages/redis/connection.py", line 256, in readline
    self._read_from_socket()
  File "/home/olcaey/koytola/venv/lib/python3.8/site-packages/redis/connection.py", line 201, in _read_from_socket
    raise ConnectionError(SERVER_CLOSED_CONNECTION_ERROR)
redis.exceptions.ConnectionError: Connection closed by server.
[2021-08-12 06:56:41,188: ERROR/MainProcess] consumer: Cannot connect to redis://localhost:6379/1: Error 111 connecting to localhost:6379. Connection refused..
Trying again in 2.00 seconds... (1/100)

[2021-08-12 06:56:41,192: ERROR/MainProcess] consumer: Cannot connect to redis://localhost:6379/1: Error 111 connecting to localhost:6379. Connection refused..
Trying again in 2.00 seconds... (1/100)

[2021-08-12 06:56:41,216: ERROR/MainProcess] consumer: Cannot connect to redis://localhost:6379/1: Error 111 connecting to localhost:6379. Connection refused..
Trying again in 2.00 seconds... (1/100)

[2021-08-12 06:56:41,246: ERROR/MainProcess] consumer: Cannot connect to redis://localhost:6379/1: Error 111 connecting to localhost:6379. Connection refused..
Trying again in 2.00 seconds... (1/100)

[2021-08-12 06:56:41,247: ERROR/MainProcess] consumer: Cannot connect to redis://localhost:6379/1: Error 111 connecting to localhost:6379. Connection refused..
Trying again in 2.00 seconds... (1/100)

[2021-08-12 06:56:43,194: INFO/MainProcess] Connected to redis://localhost:6379/1
[2021-08-12 06:56:43,203: INFO/MainProcess] Connected to redis://localhost:6379/1
[2021-08-12 06:56:43,257: INFO/MainProcess] Connected to redis://localhost:6379/1
[2021-08-12 06:56:43,270: INFO/MainProcess] mingle: searching for neighbors
[2021-08-12 06:56:43,276: INFO/MainProcess] mingle: searching for neighbors
[2021-08-12 06:56:43,280: INFO/MainProcess] Connected to redis://localhost:6379/1
[2021-08-12 06:56:43,289: INFO/MainProcess] Connected to redis://localhost:6379/1
[2021-08-12 06:56:43,316: INFO/MainProcess] mingle: searching for neighbors
[2021-08-12 06:56:43,334: INFO/MainProcess] mingle: searching for neighbors
[2021-08-12 06:56:43,341: INFO/MainProcess] mingle: searching for neighbors
[2021-08-12 06:56:44,289: INFO/MainProcess] mingle: all alone
[2021-08-12 06:56:44,295: INFO/MainProcess] mingle: all alone
[2021-08-12 06:56:44,333: INFO/MainProcess] mingle: all alone
[2021-08-12 06:56:44,341: INFO/MainProcess] mingle: all alone
[2021-08-12 06:56:44,351: INFO/MainProcess] mingle: all alone
[2021-08-12 07:01:44,645: WARNING/MainProcess] consumer: Connection to broker lost. Trying to re-establish the connection...
Traceback (most recent call last):
  File "/home/olcaey/koytola/venv/lib/python3.8/site-packages/celery/worker/consumer/consumer.py", line 318, in start
    blueprint.start(self)
  File "/home/olcaey/koytola/venv/lib/python3.8/site-packages/celery/bootsteps.py", line 119, in start
    step.start(parent)
  File "/home/olcaey/koytola/venv/lib/python3.8/site-packages/celery/worker/consumer/consumer.py", line 599, in start
    c.loop(*c.loop_args())
  File "/home/olcaey/koytola/venv/lib/python3.8/site-packages/celery/worker/loops.py", line 83, in asynloop
    next(loop)
  File "/home/olcaey/koytola/venv/lib/python3.8/site-packages/kombu/asynchronous/hub.py", line 364, in create_loop
    cb(*cbargs)
  File "/home/olcaey/koytola/venv/lib/python3.8/site-packages/kombu/transport/redis.py", line 1083, in on_readable
    self.cycle.on_readable(fileno)
  File "/home/olcaey/koytola/venv/lib/python3.8/site-packages/kombu/transport/redis.py", line 354, in on_readable
    chan.handlers[type]()
  File "/home/olcaey/koytola/venv/lib/python3.8/site-packages/kombu/transport/redis.py", line 688, in _receive
    ret.append(self._receive_one(c))
  File "/home/olcaey/koytola/venv/lib/python3.8/site-packages/kombu/transport/redis.py", line 698, in _receive_one
    response = c.parse_response()
  File "/home/olcaey/koytola/venv/lib/python3.8/site-packages/redis/client.py", line 3505, in parse_response
    response = self._execute(conn, conn.read_response)
  File "/home/olcaey/koytola/venv/lib/python3.8/site-packages/redis/client.py", line 3479, in _execute
    return command(*args, **kwargs)
  File "/home/olcaey/koytola/venv/lib/python3.8/site-packages/redis/connection.py", line 739, in read_response
    response = self._parser.read_response()
  File "/home/olcaey/koytola/venv/lib/python3.8/site-packages/redis/connection.py", line 324, in read_response
    raw = self._buffer.readline()
  File "/home/olcaey/koytola/venv/lib/python3.8/site-packages/redis/connection.py", line 256, in readline
    self._read_from_socket()
  File "/home/olcaey/koytola/venv/lib/python3.8/site-packages/redis/connection.py", line 201, in _read_from_socket
    raise ConnectionError(SERVER_CLOSED_CONNECTION_ERROR)
redis.exceptions.ConnectionError: Connection closed by server.
[2021-08-12 07:01:44,654: WARNING/MainProcess] consumer: Connection to broker lost. Trying to re-establish the connection...
Traceback (most recent call last):
  File "/home/olcaey/koytola/venv/lib/python3.8/site-packages/celery/worker/consumer/consumer.py", line 318, in start
    blueprint.start(self)
  File "/home/olcaey/koytola/venv/lib/python3.8/site-packages/celery/bootsteps.py", line 119, in start
    step.start(parent)
  File "/home/olcaey/koytola/venv/lib/python3.8/site-packages/celery/worker/consumer/consumer.py", line 599, in start
    c.loop(*c.loop_args())
  File "/home/olcaey/koytola/venv/lib/python3.8/site-packages/celery/worker/loops.py", line 83, in asynloop
    next(loop)
  File "/home/olcaey/koytola/venv/lib/python3.8/site-packages/kombu/asynchronous/hub.py", line 364, in create_loop
    cb(*cbargs)
  File "/home/olcaey/koytola/venv/lib/python3.8/site-packages/kombu/transport/redis.py", line 1083, in on_readable
    self.cycle.on_readable(fileno)
  File "/home/olcaey/koytola/venv/lib/python3.8/site-packages/kombu/transport/redis.py", line 354, in on_readable
    chan.handlers[type]()
  File "/home/olcaey/koytola/venv/lib/python3.8/site-packages/kombu/transport/redis.py", line 688, in _receive
    ret.append(self._receive_one(c))
  File "/home/olcaey/koytola/venv/lib/python3.8/site-packages/kombu/transport/redis.py", line 698, in _receive_one
    response = c.parse_response()
  File "/home/olcaey/koytola/venv/lib/python3.8/site-packages/redis/client.py", line 3505, in parse_response
    response = self._execute(conn, conn.read_response)
  File "/home/olcaey/koytola/venv/lib/python3.8/site-packages/redis/client.py", line 3479, in _execute
    return command(*args, **kwargs)
  File "/home/olcaey/koytola/venv/lib/python3.8/site-packages/redis/connection.py", line 739, in read_response
    response = self._parser.read_response()
  File "/home/olcaey/koytola/venv/lib/python3.8/site-packages/redis/connection.py", line 324, in read_response
    raw = self._buffer.readline()
  File "/home/olcaey/koytola/venv/lib/python3.8/site-packages/redis/connection.py", line 256, in readline
    self._read_from_socket()
  File "/home/olcaey/koytola/venv/lib/python3.8/site-packages/redis/connection.py", line 201, in _read_from_socket
    raise ConnectionError(SERVER_CLOSED_CONNECTION_ERROR)
redis.exceptions.ConnectionError: Connection closed by server.
[2021-08-12 07:01:44,658: WARNING/MainProcess] consumer: Connection to broker lost. Trying to re-establish the connection...
Traceback (most recent call last):
  File "/home/olcaey/koytola/venv/lib/python3.8/site-packages/celery/worker/consumer/consumer.py", line 318, in start
    blueprint.start(self)
  File "/home/olcaey/koytola/venv/lib/python3.8/site-packages/celery/bootsteps.py", line 119, in start
    step.start(parent)
  File "/home/olcaey/koytola/venv/lib/python3.8/site-packages/celery/worker/consumer/consumer.py", line 599, in start
    c.loop(*c.loop_args())
  File "/home/olcaey/koytola/venv/lib/python3.8/site-packages/celery/worker/loops.py", line 83, in asynloop
    next(loop)
  File "/home/olcaey/koytola/venv/lib/python3.8/site-packages/kombu/asynchronous/hub.py", line 364, in create_loop
    cb(*cbargs)
  File "/home/olcaey/koytola/venv/lib/python3.8/site-packages/kombu/transport/redis.py", line 1083, in on_readable
    self.cycle.on_readable(fileno)
  File "/home/olcaey/koytola/venv/lib/python3.8/site-packages/kombu/transport/redis.py", line 354, in on_readable
    chan.handlers[type]()
  File "/home/olcaey/koytola/venv/lib/python3.8/site-packages/kombu/transport/redis.py", line 688, in _receive
    ret.append(self._receive_one(c))
  File "/home/olcaey/koytola/venv/lib/python3.8/site-packages/kombu/transport/redis.py", line 698, in _receive_one
    response = c.parse_response()
  File "/home/olcaey/koytola/venv/lib/python3.8/site-packages/redis/client.py", line 3505, in parse_response
    response = self._execute(conn, conn.read_response)
  File "/home/olcaey/koytola/venv/lib/python3.8/site-packages/redis/client.py", line 3479, in _execute
    return command(*args, **kwargs)
  File "/home/olcaey/koytola/venv/lib/python3.8/site-packages/redis/connection.py", line 739, in read_response
    response = self._parser.read_response()
  File "/home/olcaey/koytola/venv/lib/python3.8/site-packages/redis/connection.py", line 324, in read_response
    raw = self._buffer.readline()
  File "/home/olcaey/koytola/venv/lib/python3.8/site-packages/redis/connection.py", line 256, in readline
    self._read_from_socket()
  File "/home/olcaey/koytola/venv/lib/python3.8/site-packages/redis/connection.py", line 201, in _read_from_socket
    raise ConnectionError(SERVER_CLOSED_CONNECTION_ERROR)
redis.exceptions.ConnectionError: Connection closed by server.
[2021-08-12 07:01:44,663: WARNING/MainProcess] consumer: Connection to broker lost. Trying to re-establish the connection...
Traceback (most recent call last):
  File "/home/olcaey/koytola/venv/lib/python3.8/site-packages/celery/worker/consumer/consumer.py", line 318, in start
    blueprint.start(self)
  File "/home/olcaey/koytola/venv/lib/python3.8/site-packages/celery/bootsteps.py", line 119, in start
    step.start(parent)
  File "/home/olcaey/koytola/venv/lib/python3.8/site-packages/celery/worker/consumer/consumer.py", line 599, in start
    c.loop(*c.loop_args())
  File "/home/olcaey/koytola/venv/lib/python3.8/site-packages/celery/worker/loops.py", line 83, in asynloop
    next(loop)
  File "/home/olcaey/koytola/venv/lib/python3.8/site-packages/kombu/asynchronous/hub.py", line 364, in create_loop
    cb(*cbargs)
  File "/home/olcaey/koytola/venv/lib/python3.8/site-packages/kombu/transport/redis.py", line 1083, in on_readable
    self.cycle.on_readable(fileno)
  File "/home/olcaey/koytola/venv/lib/python3.8/site-packages/kombu/transport/redis.py", line 354, in on_readable
    chan.handlers[type]()
  File "/home/olcaey/koytola/venv/lib/python3.8/site-packages/kombu/transport/redis.py", line 688, in _receive
    ret.append(self._receive_one(c))
  File "/home/olcaey/koytola/venv/lib/python3.8/site-packages/kombu/transport/redis.py", line 698, in _receive_one
    response = c.parse_response()
  File "/home/olcaey/koytola/venv/lib/python3.8/site-packages/redis/client.py", line 3505, in parse_response
    response = self._execute(conn, conn.read_response)
  File "/home/olcaey/koytola/venv/lib/python3.8/site-packages/redis/client.py", line 3479, in _execute
    return command(*args, **kwargs)
  File "/home/olcaey/koytola/venv/lib/python3.8/site-packages/redis/connection.py", line 739, in read_response
    response = self._parser.read_response()
  File "/home/olcaey/koytola/venv/lib/python3.8/site-packages/redis/connection.py", line 324, in read_response
    raw = self._buffer.readline()
  File "/home/olcaey/koytola/venv/lib/python3.8/site-packages/redis/connection.py", line 256, in readline
    self._read_from_socket()
  File "/home/olcaey/koytola/venv/lib/python3.8/site-packages/redis/connection.py", line 201, in _read_from_socket
    raise ConnectionError(SERVER_CLOSED_CONNECTION_ERROR)
redis.exceptions.ConnectionError: Connection closed by server.
[2021-08-12 07:01:44,665: WARNING/MainProcess] consumer: Connection to broker lost. Trying to re-establish the connection...
Traceback (most recent call last):
  File "/home/olcaey/koytola/venv/lib/python3.8/site-packages/celery/worker/consumer/consumer.py", line 318, in start
    blueprint.start(self)
  File "/home/olcaey/koytola/venv/lib/python3.8/site-packages/celery/bootsteps.py", line 119, in start
    step.start(parent)
  File "/home/olcaey/koytola/venv/lib/python3.8/site-packages/celery/worker/consumer/consumer.py", line 599, in start
    c.loop(*c.loop_args())
  File "/home/olcaey/koytola/venv/lib/python3.8/site-packages/celery/worker/loops.py", line 83, in asynloop
    next(loop)
  File "/home/olcaey/koytola/venv/lib/python3.8/site-packages/kombu/asynchronous/hub.py", line 364, in create_loop
    cb(*cbargs)
  File "/home/olcaey/koytola/venv/lib/python3.8/site-packages/kombu/transport/redis.py", line 1083, in on_readable
    self.cycle.on_readable(fileno)
  File "/home/olcaey/koytola/venv/lib/python3.8/site-packages/kombu/transport/redis.py", line 354, in on_readable
    chan.handlers[type]()
  File "/home/olcaey/koytola/venv/lib/python3.8/site-packages/kombu/transport/redis.py", line 688, in _receive
    ret.append(self._receive_one(c))
  File "/home/olcaey/koytola/venv/lib/python3.8/site-packages/kombu/transport/redis.py", line 698, in _receive_one
    response = c.parse_response()
  File "/home/olcaey/koytola/venv/lib/python3.8/site-packages/redis/client.py", line 3505, in parse_response
    response = self._execute(conn, conn.read_response)
  File "/home/olcaey/koytola/venv/lib/python3.8/site-packages/redis/client.py", line 3479, in _execute
    return command(*args, **kwargs)
  File "/home/olcaey/koytola/venv/lib/python3.8/site-packages/redis/connection.py", line 739, in read_response
    response = self._parser.read_response()
  File "/home/olcaey/koytola/venv/lib/python3.8/site-packages/redis/connection.py", line 324, in read_response
    raw = self._buffer.readline()
  File "/home/olcaey/koytola/venv/lib/python3.8/site-packages/redis/connection.py", line 256, in readline
    self._read_from_socket()
  File "/home/olcaey/koytola/venv/lib/python3.8/site-packages/redis/connection.py", line 201, in _read_from_socket
    raise ConnectionError(SERVER_CLOSED_CONNECTION_ERROR)
redis.exceptions.ConnectionError: Connection closed by server.
[2021-08-12 07:01:44,698: ERROR/MainProcess] consumer: Cannot connect to redis://localhost:6379/1: Error 111 connecting to localhost:6379. Connection refused..
Trying again in 2.00 seconds... (1/100)

[2021-08-12 07:01:44,701: ERROR/MainProcess] consumer: Cannot connect to redis://localhost:6379/1: Error 111 connecting to localhost:6379. Connection refused..
Trying again in 2.00 seconds... (1/100)

[2021-08-12 07:01:44,712: ERROR/MainProcess] consumer: Cannot connect to redis://localhost:6379/1: Error 111 connecting to localhost:6379. Connection refused..
Trying again in 2.00 seconds... (1/100)

[2021-08-12 07:01:44,725: ERROR/MainProcess] consumer: Cannot connect to redis://localhost:6379/1: Error 111 connecting to localhost:6379. Connection refused..
Trying again in 2.00 seconds... (1/100)

[2021-08-12 07:01:44,735: ERROR/MainProcess] consumer: Cannot connect to redis://localhost:6379/1: Error 111 connecting to localhost:6379. Connection refused..
Trying again in 2.00 seconds... (1/100)

[2021-08-12 07:01:46,708: INFO/MainProcess] Connected to redis://localhost:6379/1
[2021-08-12 07:01:46,717: INFO/MainProcess] Connected to redis://localhost:6379/1
[2021-08-12 07:01:46,733: INFO/MainProcess] mingle: searching for neighbors
[2021-08-12 07:01:46,739: INFO/MainProcess] Connected to redis://localhost:6379/1
[2021-08-12 07:01:46,742: INFO/MainProcess] Connected to redis://localhost:6379/1
[2021-08-12 07:01:46,745: INFO/MainProcess] Connected to redis://localhost:6379/1
[2021-08-12 07:01:46,769: INFO/MainProcess] mingle: searching for neighbors
[2021-08-12 07:01:46,772: INFO/MainProcess] mingle: searching for neighbors
[2021-08-12 07:01:46,777: INFO/MainProcess] mingle: searching for neighbors
[2021-08-12 07:01:46,778: INFO/MainProcess] mingle: searching for neighbors
[2021-08-12 07:01:47,740: INFO/MainProcess] mingle: all alone
[2021-08-12 07:01:47,777: INFO/MainProcess] mingle: all alone
[2021-08-12 07:01:47,781: INFO/MainProcess] mingle: all alone
[2021-08-12 07:01:47,786: INFO/MainProcess] mingle: all alone
[2021-08-12 07:01:47,787: INFO/MainProcess] mingle: all alone
[2021-08-12 07:01:55,723: WARNING/MainProcess] consumer: Connection to broker lost. Trying to re-establish the connection...
Traceback (most recent call last):
  File "/home/olcaey/koytola/venv/lib/python3.8/site-packages/celery/worker/consumer/consumer.py", line 318, in start
    blueprint.start(self)
  File "/home/olcaey/koytola/venv/lib/python3.8/site-packages/celery/bootsteps.py", line 119, in start
    step.start(parent)
  File "/home/olcaey/koytola/venv/lib/python3.8/site-packages/celery/worker/consumer/consumer.py", line 599, in start
    c.loop(*c.loop_args())
  File "/home/olcaey/koytola/venv/lib/python3.8/site-packages/celery/worker/loops.py", line 83, in asynloop
    next(loop)
  File "/home/olcaey/koytola/venv/lib/python3.8/site-packages/kombu/asynchronous/hub.py", line 364, in create_loop
    cb(*cbargs)
  File "/home/olcaey/koytola/venv/lib/python3.8/site-packages/kombu/transport/redis.py", line 1083, in on_readable
    self.cycle.on_readable(fileno)
  File "/home/olcaey/koytola/venv/lib/python3.8/site-packages/kombu/transport/redis.py", line 354, in on_readable
    chan.handlers[type]()
  File "/home/olcaey/koytola/venv/lib/python3.8/site-packages/kombu/transport/redis.py", line 688, in _receive
    ret.append(self._receive_one(c))
  File "/home/olcaey/koytola/venv/lib/python3.8/site-packages/kombu/transport/redis.py", line 698, in _receive_one
    response = c.parse_response()
  File "/home/olcaey/koytola/venv/lib/python3.8/site-packages/redis/client.py", line 3505, in parse_response
    response = self._execute(conn, conn.read_response)
  File "/home/olcaey/koytola/venv/lib/python3.8/site-packages/redis/client.py", line 3479, in _execute
    return command(*args, **kwargs)
  File "/home/olcaey/koytola/venv/lib/python3.8/site-packages/redis/connection.py", line 739, in read_response
    response = self._parser.read_response()
  File "/home/olcaey/koytola/venv/lib/python3.8/site-packages/redis/connection.py", line 324, in read_response
    raw = self._buffer.readline()
  File "/home/olcaey/koytola/venv/lib/python3.8/site-packages/redis/connection.py", line 256, in readline
    self._read_from_socket()
  File "/home/olcaey/koytola/venv/lib/python3.8/site-packages/redis/connection.py", line 201, in _read_from_socket
    raise ConnectionError(SERVER_CLOSED_CONNECTION_ERROR)
redis.exceptions.ConnectionError: Connection closed by server.
[2021-08-12 07:01:55,730: WARNING/MainProcess] consumer: Connection to broker lost. Trying to re-establish the connection...
Traceback (most recent call last):
  File "/home/olcaey/koytola/venv/lib/python3.8/site-packages/celery/worker/consumer/consumer.py", line 318, in start
    blueprint.start(self)
  File "/home/olcaey/koytola/venv/lib/python3.8/site-packages/celery/bootsteps.py", line 119, in start
    step.start(parent)
  File "/home/olcaey/koytola/venv/lib/python3.8/site-packages/celery/worker/consumer/consumer.py", line 599, in start
    c.loop(*c.loop_args())
  File "/home/olcaey/koytola/venv/lib/python3.8/site-packages/celery/worker/loops.py", line 83, in asynloop
    next(loop)
  File "/home/olcaey/koytola/venv/lib/python3.8/site-packages/kombu/asynchronous/hub.py", line 364, in create_loop
    cb(*cbargs)
  File "/home/olcaey/koytola/venv/lib/python3.8/site-packages/kombu/transport/redis.py", line 1083, in on_readable
    self.cycle.on_readable(fileno)
  File "/home/olcaey/koytola/venv/lib/python3.8/site-packages/kombu/transport/redis.py", line 354, in on_readable
    chan.handlers[type]()
  File "/home/olcaey/koytola/venv/lib/python3.8/site-packages/kombu/transport/redis.py", line 688, in _receive
    ret.append(self._receive_one(c))
  File "/home/olcaey/koytola/venv/lib/python3.8/site-packages/kombu/transport/redis.py", line 698, in _receive_one
    response = c.parse_response()
  File "/home/olcaey/koytola/venv/lib/python3.8/site-packages/redis/client.py", line 3505, in parse_response
    response = self._execute(conn, conn.read_response)
  File "/home/olcaey/koytola/venv/lib/python3.8/site-packages/redis/client.py", line 3479, in _execute
    return command(*args, **kwargs)
  File "/home/olcaey/koytola/venv/lib/python3.8/site-packages/redis/connection.py", line 739, in read_response
    response = self._parser.read_response()
  File "/home/olcaey/koytola/venv/lib/python3.8/site-packages/redis/connection.py", line 324, in read_response
    raw = self._buffer.readline()
  File "/home/olcaey/koytola/venv/lib/python3.8/site-packages/redis/connection.py", line 256, in readline
    self._read_from_socket()
  File "/home/olcaey/koytola/venv/lib/python3.8/site-packages/redis/connection.py", line 201, in _read_from_socket
    raise ConnectionError(SERVER_CLOSED_CONNECTION_ERROR)
redis.exceptions.ConnectionError: Connection closed by server.
[2021-08-12 07:01:55,734: WARNING/MainProcess] consumer: Connection to broker lost. Trying to re-establish the connection...
Traceback (most recent call last):
  File "/home/olcaey/koytola/venv/lib/python3.8/site-packages/celery/worker/consumer/consumer.py", line 318, in start
    blueprint.start(self)
  File "/home/olcaey/koytola/venv/lib/python3.8/site-packages/celery/bootsteps.py", line 119, in start
    step.start(parent)
  File "/home/olcaey/koytola/venv/lib/python3.8/site-packages/celery/worker/consumer/consumer.py", line 599, in start
    c.loop(*c.loop_args())
  File "/home/olcaey/koytola/venv/lib/python3.8/site-packages/celery/worker/loops.py", line 83, in asynloop
    next(loop)
  File "/home/olcaey/koytola/venv/lib/python3.8/site-packages/kombu/asynchronous/hub.py", line 364, in create_loop
    cb(*cbargs)
  File "/home/olcaey/koytola/venv/lib/python3.8/site-packages/kombu/transport/redis.py", line 1083, in on_readable
    self.cycle.on_readable(fileno)
  File "/home/olcaey/koytola/venv/lib/python3.8/site-packages/kombu/transport/redis.py", line 354, in on_readable
    chan.handlers[type]()
  File "/home/olcaey/koytola/venv/lib/python3.8/site-packages/kombu/transport/redis.py", line 688, in _receive
    ret.append(self._receive_one(c))
  File "/home/olcaey/koytola/venv/lib/python3.8/site-packages/kombu/transport/redis.py", line 698, in _receive_one
    response = c.parse_response()
  File "/home/olcaey/koytola/venv/lib/python3.8/site-packages/redis/client.py", line 3505, in parse_response
    response = self._execute(conn, conn.read_response)
  File "/home/olcaey/koytola/venv/lib/python3.8/site-packages/redis/client.py", line 3479, in _execute
    return command(*args, **kwargs)
  File "/home/olcaey/koytola/venv/lib/python3.8/site-packages/redis/connection.py", line 739, in read_response
    response = self._parser.read_response()
  File "/home/olcaey/koytola/venv/lib/python3.8/site-packages/redis/connection.py", line 324, in read_response
    raw = self._buffer.readline()
  File "/home/olcaey/koytola/venv/lib/python3.8/site-packages/redis/connection.py", line 256, in readline
    self._read_from_socket()
  File "/home/olcaey/koytola/venv/lib/python3.8/site-packages/redis/connection.py", line 201, in _read_from_socket
    raise ConnectionError(SERVER_CLOSED_CONNECTION_ERROR)
redis.exceptions.ConnectionError: Connection closed by server.
[2021-08-12 07:01:55,735: WARNING/MainProcess] consumer: Connection to broker lost. Trying to re-establish the connection...
Traceback (most recent call last):
  File "/home/olcaey/koytola/venv/lib/python3.8/site-packages/celery/worker/consumer/consumer.py", line 318, in start
    blueprint.start(self)
  File "/home/olcaey/koytola/venv/lib/python3.8/site-packages/celery/bootsteps.py", line 119, in start
    step.start(parent)
  File "/home/olcaey/koytola/venv/lib/python3.8/site-packages/celery/worker/consumer/consumer.py", line 599, in start
    c.loop(*c.loop_args())
  File "/home/olcaey/koytola/venv/lib/python3.8/site-packages/celery/worker/loops.py", line 83, in asynloop
    next(loop)
  File "/home/olcaey/koytola/venv/lib/python3.8/site-packages/kombu/asynchronous/hub.py", line 364, in create_loop
    cb(*cbargs)
  File "/home/olcaey/koytola/venv/lib/python3.8/site-packages/kombu/transport/redis.py", line 1083, in on_readable
    self.cycle.on_readable(fileno)
  File "/home/olcaey/koytola/venv/lib/python3.8/site-packages/kombu/transport/redis.py", line 354, in on_readable
    chan.handlers[type]()
  File "/home/olcaey/koytola/venv/lib/python3.8/site-packages/kombu/transport/redis.py", line 688, in _receive
    ret.append(self._receive_one(c))
  File "/home/olcaey/koytola/venv/lib/python3.8/site-packages/kombu/transport/redis.py", line 698, in _receive_one
    response = c.parse_response()
  File "/home/olcaey/koytola/venv/lib/python3.8/site-packages/redis/client.py", line 3505, in parse_response
    response = self._execute(conn, conn.read_response)
  File "/home/olcaey/koytola/venv/lib/python3.8/site-packages/redis/client.py", line 3479, in _execute
    return command(*args, **kwargs)
  File "/home/olcaey/koytola/venv/lib/python3.8/site-packages/redis/connection.py", line 739, in read_response
    response = self._parser.read_response()
  File "/home/olcaey/koytola/venv/lib/python3.8/site-packages/redis/connection.py", line 324, in read_response
    raw = self._buffer.readline()
  File "/home/olcaey/koytola/venv/lib/python3.8/site-packages/redis/connection.py", line 256, in readline
    self._read_from_socket()
  File "/home/olcaey/koytola/venv/lib/python3.8/site-packages/redis/connection.py", line 201, in _read_from_socket
    raise ConnectionError(SERVER_CLOSED_CONNECTION_ERROR)
redis.exceptions.ConnectionError: Connection closed by server.
[2021-08-12 07:01:55,742: WARNING/MainProcess] consumer: Connection to broker lost. Trying to re-establish the connection...
Traceback (most recent call last):
  File "/home/olcaey/koytola/venv/lib/python3.8/site-packages/celery/worker/consumer/consumer.py", line 318, in start
    blueprint.start(self)
  File "/home/olcaey/koytola/venv/lib/python3.8/site-packages/celery/bootsteps.py", line 119, in start
    step.start(parent)
  File "/home/olcaey/koytola/venv/lib/python3.8/site-packages/celery/worker/consumer/consumer.py", line 599, in start
    c.loop(*c.loop_args())
  File "/home/olcaey/koytola/venv/lib/python3.8/site-packages/celery/worker/loops.py", line 83, in asynloop
    next(loop)
  File "/home/olcaey/koytola/venv/lib/python3.8/site-packages/kombu/asynchronous/hub.py", line 364, in create_loop
    cb(*cbargs)
  File "/home/olcaey/koytola/venv/lib/python3.8/site-packages/kombu/transport/redis.py", line 1083, in on_readable
    self.cycle.on_readable(fileno)
  File "/home/olcaey/koytola/venv/lib/python3.8/site-packages/kombu/transport/redis.py", line 354, in on_readable
    chan.handlers[type]()
  File "/home/olcaey/koytola/venv/lib/python3.8/site-packages/kombu/transport/redis.py", line 688, in _receive
    ret.append(self._receive_one(c))
  File "/home/olcaey/koytola/venv/lib/python3.8/site-packages/kombu/transport/redis.py", line 698, in _receive_one
    response = c.parse_response()
  File "/home/olcaey/koytola/venv/lib/python3.8/site-packages/redis/client.py", line 3505, in parse_response
    response = self._execute(conn, conn.read_response)
  File "/home/olcaey/koytola/venv/lib/python3.8/site-packages/redis/client.py", line 3479, in _execute
    return command(*args, **kwargs)
  File "/home/olcaey/koytola/venv/lib/python3.8/site-packages/redis/connection.py", line 739, in read_response
    response = self._parser.read_response()
  File "/home/olcaey/koytola/venv/lib/python3.8/site-packages/redis/connection.py", line 324, in read_response
    raw = self._buffer.readline()
  File "/home/olcaey/koytola/venv/lib/python3.8/site-packages/redis/connection.py", line 256, in readline
    self._read_from_socket()
  File "/home/olcaey/koytola/venv/lib/python3.8/site-packages/redis/connection.py", line 201, in _read_from_socket
    raise ConnectionError(SERVER_CLOSED_CONNECTION_ERROR)
redis.exceptions.ConnectionError: Connection closed by server.
[2021-08-12 07:01:55,794: ERROR/MainProcess] consumer: Cannot connect to redis://localhost:6379/1: Error 111 connecting to localhost:6379. Connection refused..
Trying again in 2.00 seconds... (1/100)

[2021-08-12 07:01:55,796: ERROR/MainProcess] consumer: Cannot connect to redis://localhost:6379/1: Error 111 connecting to localhost:6379. Connection refused..
Trying again in 2.00 seconds... (1/100)

[2021-08-12 07:01:55,800: ERROR/MainProcess] consumer: Cannot connect to redis://localhost:6379/1: Error 111 connecting to localhost:6379. Connection refused..
Trying again in 2.00 seconds... (1/100)

[2021-08-12 07:01:55,802: ERROR/MainProcess] consumer: Cannot connect to redis://localhost:6379/1: Error 111 connecting to localhost:6379. Connection refused..
Trying again in 2.00 seconds... (1/100)

[2021-08-12 07:01:55,806: ERROR/MainProcess] consumer: Cannot connect to redis://localhost:6379/1: Error 111 connecting to localhost:6379. Connection refused..
Trying again in 2.00 seconds... (1/100)

[2021-08-12 07:01:57,800: INFO/MainProcess] Connected to redis://localhost:6379/1
[2021-08-12 07:01:57,814: INFO/MainProcess] mingle: searching for neighbors
[2021-08-12 07:01:57,823: INFO/MainProcess] Connected to redis://localhost:6379/1
[2021-08-12 07:01:57,825: INFO/MainProcess] Connected to redis://localhost:6379/1
[2021-08-12 07:01:57,831: INFO/MainProcess] Connected to redis://localhost:6379/1
[2021-08-12 07:01:57,833: INFO/MainProcess] Connected to redis://localhost:6379/1
[2021-08-12 07:01:57,842: INFO/MainProcess] mingle: searching for neighbors
[2021-08-12 07:01:57,856: INFO/MainProcess] mingle: searching for neighbors
[2021-08-12 07:01:57,869: INFO/MainProcess] mingle: searching for neighbors
[2021-08-12 07:01:57,872: INFO/MainProcess] mingle: searching for neighbors
[2021-08-12 07:01:58,821: INFO/MainProcess] mingle: all alone
[2021-08-12 07:01:58,849: INFO/MainProcess] mingle: all alone
[2021-08-12 07:01:58,861: INFO/MainProcess] mingle: all alone
[2021-08-12 07:01:58,880: INFO/MainProcess] mingle: all alone
[2021-08-12 07:01:58,882: INFO/MainProcess] mingle: all alone
/home/olcaey/koytola/venv/lib/python3.8/site-packages/graphene_django/types.py:94: UserWarning: Field name "description" doesn't exist on Django model "profile.Certificate". Consider removing the field from the "fields" list of DjangoObjectType "Certificate" because it has no effect.
  warnings.warn(
/home/olcaey/koytola/venv/lib/python3.8/site-packages/graphene_django/types.py:94: UserWarning: Field name "name" doesn't exist on Django model "profile.Certificate". Consider removing the field from the "fields" list of DjangoObjectType "Certificate" because it has no effect.
  warnings.warn(
/home/olcaey/koytola/venv/lib/python3.8/site-packages/graphene_django/types.py:94: UserWarning: Field name "content" doesn't exist on Django model "blog.Blog". Consider removing the field from the "fields" list of DjangoObjectType "BlogTranslatableContent" because it has no effect.
  warnings.warn(
/home/olcaey/koytola/venv/lib/python3.8/site-packages/graphene_django/types.py:94: UserWarning: Field name "summary" doesn't exist on Django model "blog.Blog". Consider removing the field from the "fields" list of DjangoObjectType "BlogTranslatableContent" because it has no effect.
  warnings.warn(
/home/olcaey/koytola/venv/lib/python3.8/site-packages/graphene_django/types.py:94: UserWarning: Field name "content_plaintext" doesn't exist on Django model "news.News". Consider removing the field from the "fields" list of DjangoObjectType "NewsTranslatableContent" because it has no effect.
  warnings.warn(
/home/olcaey/koytola/venv/lib/python3.8/site-packages/graphene_django/types.py:94: UserWarning: Field name "description" doesn't exist on Django model "news.News". Consider removing the field from the "fields" list of DjangoObjectType "News" because it has no effect.
  warnings.warn(
[2021-08-12 07:02:20,913: INFO/MainProcess] Connected to redis://localhost:6379/1
[2021-08-12 07:02:20,923: INFO/MainProcess] mingle: searching for neighbors
[2021-08-12 07:02:21,960: WARNING/MainProcess] /home/olcaey/koytola/venv/lib/python3.8/site-packages/celery/app/control.py:52: DuplicateNodenameWarning: Received multiple replies from node name: celery@koytola-dev.
Please make sure you give each node a unique nodename using
the celery worker `-n` option.
  warnings.warn(DuplicateNodenameWarning(
[2021-08-12 07:02:21,960: INFO/MainProcess] mingle: all alone
[2021-08-12 07:02:21,976: INFO/MainProcess] celery@koytola-dev ready.
[2021-08-12 07:02:45,935: INFO/MainProcess] Received task: koytola.account.emails._send_account_confirmation_email[d4b9c4e2-e7f9-4af6-8336-f91bc2bc15fc]  
/home/olcaey/koytola/venv/lib/python3.8/site-packages/graphene_django/types.py:94: UserWarning: Field name "description" doesn't exist on Django model "profile.Certificate". Consider removing the field from the "fields" list of DjangoObjectType "Certificate" because it has no effect.
  warnings.warn(
/home/olcaey/koytola/venv/lib/python3.8/site-packages/graphene_django/types.py:94: UserWarning: Field name "name" doesn't exist on Django model "profile.Certificate". Consider removing the field from the "fields" list of DjangoObjectType "Certificate" because it has no effect.
  warnings.warn(
/home/olcaey/koytola/venv/lib/python3.8/site-packages/graphene_django/types.py:94: UserWarning: Field name "content" doesn't exist on Django model "blog.Blog". Consider removing the field from the "fields" list of DjangoObjectType "BlogTranslatableContent" because it has no effect.
  warnings.warn(
/home/olcaey/koytola/venv/lib/python3.8/site-packages/graphene_django/types.py:94: UserWarning: Field name "summary" doesn't exist on Django model "blog.Blog". Consider removing the field from the "fields" list of DjangoObjectType "BlogTranslatableContent" because it has no effect.
  warnings.warn(
/home/olcaey/koytola/venv/lib/python3.8/site-packages/graphene_django/types.py:94: UserWarning: Field name "content_plaintext" doesn't exist on Django model "news.News". Consider removing the field from the "fields" list of DjangoObjectType "NewsTranslatableContent" because it has no effect.
  warnings.warn(
/home/olcaey/koytola/venv/lib/python3.8/site-packages/graphene_django/types.py:94: UserWarning: Field name "description" doesn't exist on Django model "news.News". Consider removing the field from the "fields" list of DjangoObjectType "News" because it has no effect.
  warnings.warn(
[2021-08-12 07:02:47,263: INFO/ForkPoolWorker-1] Task koytola.account.emails._send_account_confirmation_email[d4b9c4e2-e7f9-4af6-8336-f91bc2bc15fc] succeeded in 1.326135537121445s: None
[2021-08-12 12:41:38,723: WARNING/MainProcess] consumer: Connection to broker lost. Trying to re-establish the connection...
Traceback (most recent call last):
  File "/home/olcaey/koytola/venv/lib/python3.8/site-packages/celery/worker/consumer/consumer.py", line 318, in start
    blueprint.start(self)
  File "/home/olcaey/koytola/venv/lib/python3.8/site-packages/celery/bootsteps.py", line 119, in start
    step.start(parent)
  File "/home/olcaey/koytola/venv/lib/python3.8/site-packages/celery/worker/consumer/consumer.py", line 599, in start
    c.loop(*c.loop_args())
  File "/home/olcaey/koytola/venv/lib/python3.8/site-packages/celery/worker/loops.py", line 83, in asynloop
    next(loop)
  File "/home/olcaey/koytola/venv/lib/python3.8/site-packages/kombu/asynchronous/hub.py", line 364, in create_loop
    cb(*cbargs)
  File "/home/olcaey/koytola/venv/lib/python3.8/site-packages/kombu/transport/redis.py", line 1083, in on_readable
    self.cycle.on_readable(fileno)
  File "/home/olcaey/koytola/venv/lib/python3.8/site-packages/kombu/transport/redis.py", line 354, in on_readable
    chan.handlers[type]()
  File "/home/olcaey/koytola/venv/lib/python3.8/site-packages/kombu/transport/redis.py", line 688, in _receive
    ret.append(self._receive_one(c))
  File "/home/olcaey/koytola/venv/lib/python3.8/site-packages/kombu/transport/redis.py", line 698, in _receive_one
    response = c.parse_response()
  File "/home/olcaey/koytola/venv/lib/python3.8/site-packages/redis/client.py", line 3505, in parse_response
    response = self._execute(conn, conn.read_response)
  File "/home/olcaey/koytola/venv/lib/python3.8/site-packages/redis/client.py", line 3479, in _execute
    return command(*args, **kwargs)
  File "/home/olcaey/koytola/venv/lib/python3.8/site-packages/redis/connection.py", line 739, in read_response
    response = self._parser.read_response()
  File "/home/olcaey/koytola/venv/lib/python3.8/site-packages/redis/connection.py", line 324, in read_response
    raw = self._buffer.readline()
  File "/home/olcaey/koytola/venv/lib/python3.8/site-packages/redis/connection.py", line 256, in readline
    self._read_from_socket()
  File "/home/olcaey/koytola/venv/lib/python3.8/site-packages/redis/connection.py", line 201, in _read_from_socket
    raise ConnectionError(SERVER_CLOSED_CONNECTION_ERROR)
redis.exceptions.ConnectionError: Connection closed by server.
[2021-08-12 12:41:38,731: WARNING/MainProcess] consumer: Connection to broker lost. Trying to re-establish the connection...
Traceback (most recent call last):
  File "/home/olcaey/koytola/venv/lib/python3.8/site-packages/celery/worker/consumer/consumer.py", line 318, in start
    blueprint.start(self)
  File "/home/olcaey/koytola/venv/lib/python3.8/site-packages/celery/bootsteps.py", line 119, in start
    step.start(parent)
  File "/home/olcaey/koytola/venv/lib/python3.8/site-packages/celery/worker/consumer/consumer.py", line 599, in start
    c.loop(*c.loop_args())
  File "/home/olcaey/koytola/venv/lib/python3.8/site-packages/celery/worker/loops.py", line 83, in asynloop
    next(loop)
  File "/home/olcaey/koytola/venv/lib/python3.8/site-packages/kombu/asynchronous/hub.py", line 364, in create_loop
    cb(*cbargs)
  File "/home/olcaey/koytola/venv/lib/python3.8/site-packages/kombu/transport/redis.py", line 1083, in on_readable
    self.cycle.on_readable(fileno)
  File "/home/olcaey/koytola/venv/lib/python3.8/site-packages/kombu/transport/redis.py", line 354, in on_readable
    chan.handlers[type]()
  File "/home/olcaey/koytola/venv/lib/python3.8/site-packages/kombu/transport/redis.py", line 688, in _receive
    ret.append(self._receive_one(c))
  File "/home/olcaey/koytola/venv/lib/python3.8/site-packages/kombu/transport/redis.py", line 698, in _receive_one
    response = c.parse_response()
  File "/home/olcaey/koytola/venv/lib/python3.8/site-packages/redis/client.py", line 3505, in parse_response
    response = self._execute(conn, conn.read_response)
  File "/home/olcaey/koytola/venv/lib/python3.8/site-packages/redis/client.py", line 3479, in _execute
    return command(*args, **kwargs)
  File "/home/olcaey/koytola/venv/lib/python3.8/site-packages/redis/connection.py", line 739, in read_response
    response = self._parser.read_response()
  File "/home/olcaey/koytola/venv/lib/python3.8/site-packages/redis/connection.py", line 324, in read_response
    raw = self._buffer.readline()
  File "/home/olcaey/koytola/venv/lib/python3.8/site-packages/redis/connection.py", line 256, in readline
    self._read_from_socket()
  File "/home/olcaey/koytola/venv/lib/python3.8/site-packages/redis/connection.py", line 201, in _read_from_socket
    raise ConnectionError(SERVER_CLOSED_CONNECTION_ERROR)
redis.exceptions.ConnectionError: Connection closed by server.
[2021-08-12 12:41:38,733: WARNING/MainProcess] consumer: Connection to broker lost. Trying to re-establish the connection...
Traceback (most recent call last):
  File "/home/olcaey/koytola/venv/lib/python3.8/site-packages/celery/worker/consumer/consumer.py", line 318, in start
    blueprint.start(self)
  File "/home/olcaey/koytola/venv/lib/python3.8/site-packages/celery/bootsteps.py", line 119, in start
    step.start(parent)
  File "/home/olcaey/koytola/venv/lib/python3.8/site-packages/celery/worker/consumer/consumer.py", line 599, in start
    c.loop(*c.loop_args())
  File "/home/olcaey/koytola/venv/lib/python3.8/site-packages/celery/worker/loops.py", line 83, in asynloop
    next(loop)
  File "/home/olcaey/koytola/venv/lib/python3.8/site-packages/kombu/asynchronous/hub.py", line 364, in create_loop
    cb(*cbargs)
  File "/home/olcaey/koytola/venv/lib/python3.8/site-packages/kombu/transport/redis.py", line 1083, in on_readable
    self.cycle.on_readable(fileno)
  File "/home/olcaey/koytola/venv/lib/python3.8/site-packages/kombu/transport/redis.py", line 354, in on_readable
    chan.handlers[type]()
  File "/home/olcaey/koytola/venv/lib/python3.8/site-packages/kombu/transport/redis.py", line 688, in _receive
    ret.append(self._receive_one(c))
  File "/home/olcaey/koytola/venv/lib/python3.8/site-packages/kombu/transport/redis.py", line 698, in _receive_one
    response = c.parse_response()
  File "/home/olcaey/koytola/venv/lib/python3.8/site-packages/redis/client.py", line 3505, in parse_response
    response = self._execute(conn, conn.read_response)
  File "/home/olcaey/koytola/venv/lib/python3.8/site-packages/redis/client.py", line 3479, in _execute
    return command(*args, **kwargs)
  File "/home/olcaey/koytola/venv/lib/python3.8/site-packages/redis/connection.py", line 739, in read_response
    response = self._parser.read_response()
  File "/home/olcaey/koytola/venv/lib/python3.8/site-packages/redis/connection.py", line 324, in read_response
    raw = self._buffer.readline()
  File "/home/olcaey/koytola/venv/lib/python3.8/site-packages/redis/connection.py", line 256, in readline
    self._read_from_socket()
  File "/home/olcaey/koytola/venv/lib/python3.8/site-packages/redis/connection.py", line 201, in _read_from_socket
    raise ConnectionError(SERVER_CLOSED_CONNECTION_ERROR)
redis.exceptions.ConnectionError: Connection closed by server.
[2021-08-12 12:41:38,728: WARNING/MainProcess] consumer: Connection to broker lost. Trying to re-establish the connection...
Traceback (most recent call last):
  File "/home/olcaey/koytola/venv/lib/python3.8/site-packages/celery/worker/consumer/consumer.py", line 318, in start
    blueprint.start(self)
  File "/home/olcaey/koytola/venv/lib/python3.8/site-packages/celery/bootsteps.py", line 119, in start
    step.start(parent)
  File "/home/olcaey/koytola/venv/lib/python3.8/site-packages/celery/worker/consumer/consumer.py", line 599, in start
    c.loop(*c.loop_args())
  File "/home/olcaey/koytola/venv/lib/python3.8/site-packages/celery/worker/loops.py", line 83, in asynloop
    next(loop)
  File "/home/olcaey/koytola/venv/lib/python3.8/site-packages/kombu/asynchronous/hub.py", line 364, in create_loop
    cb(*cbargs)
  File "/home/olcaey/koytola/venv/lib/python3.8/site-packages/kombu/transport/redis.py", line 1083, in on_readable
    self.cycle.on_readable(fileno)
  File "/home/olcaey/koytola/venv/lib/python3.8/site-packages/kombu/transport/redis.py", line 354, in on_readable
    chan.handlers[type]()
  File "/home/olcaey/koytola/venv/lib/python3.8/site-packages/kombu/transport/redis.py", line 688, in _receive
    ret.append(self._receive_one(c))
  File "/home/olcaey/koytola/venv/lib/python3.8/site-packages/kombu/transport/redis.py", line 698, in _receive_one
    response = c.parse_response()
  File "/home/olcaey/koytola/venv/lib/python3.8/site-packages/redis/client.py", line 3505, in parse_response
    response = self._execute(conn, conn.read_response)
  File "/home/olcaey/koytola/venv/lib/python3.8/site-packages/redis/client.py", line 3479, in _execute
    return command(*args, **kwargs)
  File "/home/olcaey/koytola/venv/lib/python3.8/site-packages/redis/connection.py", line 739, in read_response
    response = self._parser.read_response()
  File "/home/olcaey/koytola/venv/lib/python3.8/site-packages/redis/connection.py", line 324, in read_response
    raw = self._buffer.readline()
  File "/home/olcaey/koytola/venv/lib/python3.8/site-packages/redis/connection.py", line 256, in readline
    self._read_from_socket()
  File "/home/olcaey/koytola/venv/lib/python3.8/site-packages/redis/connection.py", line 201, in _read_from_socket
    raise ConnectionError(SERVER_CLOSED_CONNECTION_ERROR)
redis.exceptions.ConnectionError: Connection closed by server.
[2021-08-12 12:41:38,742: WARNING/MainProcess] consumer: Connection to broker lost. Trying to re-establish the connection...
Traceback (most recent call last):
  File "/home/olcaey/koytola/venv/lib/python3.8/site-packages/celery/worker/consumer/consumer.py", line 318, in start
    blueprint.start(self)
  File "/home/olcaey/koytola/venv/lib/python3.8/site-packages/celery/bootsteps.py", line 119, in start
    step.start(parent)
  File "/home/olcaey/koytola/venv/lib/python3.8/site-packages/celery/worker/consumer/consumer.py", line 599, in start
    c.loop(*c.loop_args())
  File "/home/olcaey/koytola/venv/lib/python3.8/site-packages/celery/worker/loops.py", line 83, in asynloop
    next(loop)
  File "/home/olcaey/koytola/venv/lib/python3.8/site-packages/kombu/asynchronous/hub.py", line 364, in create_loop
    cb(*cbargs)
  File "/home/olcaey/koytola/venv/lib/python3.8/site-packages/kombu/transport/redis.py", line 1083, in on_readable
    self.cycle.on_readable(fileno)
  File "/home/olcaey/koytola/venv/lib/python3.8/site-packages/kombu/transport/redis.py", line 354, in on_readable
    chan.handlers[type]()
  File "/home/olcaey/koytola/venv/lib/python3.8/site-packages/kombu/transport/redis.py", line 688, in _receive
    ret.append(self._receive_one(c))
  File "/home/olcaey/koytola/venv/lib/python3.8/site-packages/kombu/transport/redis.py", line 698, in _receive_one
    response = c.parse_response()
  File "/home/olcaey/koytola/venv/lib/python3.8/site-packages/redis/client.py", line 3505, in parse_response
    response = self._execute(conn, conn.read_response)
  File "/home/olcaey/koytola/venv/lib/python3.8/site-packages/redis/client.py", line 3479, in _execute
    return command(*args, **kwargs)
  File "/home/olcaey/koytola/venv/lib/python3.8/site-packages/redis/connection.py", line 739, in read_response
    response = self._parser.read_response()
  File "/home/olcaey/koytola/venv/lib/python3.8/site-packages/redis/connection.py", line 324, in read_response
    raw = self._buffer.readline()
  File "/home/olcaey/koytola/venv/lib/python3.8/site-packages/redis/connection.py", line 256, in readline
    self._read_from_socket()
  File "/home/olcaey/koytola/venv/lib/python3.8/site-packages/redis/connection.py", line 201, in _read_from_socket
    raise ConnectionError(SERVER_CLOSED_CONNECTION_ERROR)
redis.exceptions.ConnectionError: Connection closed by server.
[2021-08-12 12:41:38,718: WARNING/MainProcess] consumer: Connection to broker lost. Trying to re-establish the connection...
Traceback (most recent call last):
  File "/home/olcaey/koytola/venv/lib/python3.8/site-packages/celery/worker/consumer/consumer.py", line 318, in start
    blueprint.start(self)
  File "/home/olcaey/koytola/venv/lib/python3.8/site-packages/celery/bootsteps.py", line 119, in start
    step.start(parent)
  File "/home/olcaey/koytola/venv/lib/python3.8/site-packages/celery/worker/consumer/consumer.py", line 599, in start
    c.loop(*c.loop_args())
  File "/home/olcaey/koytola/venv/lib/python3.8/site-packages/celery/worker/loops.py", line 83, in asynloop
    next(loop)
  File "/home/olcaey/koytola/venv/lib/python3.8/site-packages/kombu/asynchronous/hub.py", line 364, in create_loop
    cb(*cbargs)
  File "/home/olcaey/koytola/venv/lib/python3.8/site-packages/kombu/transport/redis.py", line 1083, in on_readable
    self.cycle.on_readable(fileno)
  File "/home/olcaey/koytola/venv/lib/python3.8/site-packages/kombu/transport/redis.py", line 354, in on_readable
    chan.handlers[type]()
  File "/home/olcaey/koytola/venv/lib/python3.8/site-packages/kombu/transport/redis.py", line 688, in _receive
    ret.append(self._receive_one(c))
  File "/home/olcaey/koytola/venv/lib/python3.8/site-packages/kombu/transport/redis.py", line 698, in _receive_one
    response = c.parse_response()
  File "/home/olcaey/koytola/venv/lib/python3.8/site-packages/redis/client.py", line 3505, in parse_response
    response = self._execute(conn, conn.read_response)
  File "/home/olcaey/koytola/venv/lib/python3.8/site-packages/redis/client.py", line 3479, in _execute
    return command(*args, **kwargs)
  File "/home/olcaey/koytola/venv/lib/python3.8/site-packages/redis/connection.py", line 739, in read_response
    response = self._parser.read_response()
  File "/home/olcaey/koytola/venv/lib/python3.8/site-packages/redis/connection.py", line 324, in read_response
    raw = self._buffer.readline()
  File "/home/olcaey/koytola/venv/lib/python3.8/site-packages/redis/connection.py", line 256, in readline
    self._read_from_socket()
  File "/home/olcaey/koytola/venv/lib/python3.8/site-packages/redis/connection.py", line 201, in _read_from_socket
    raise ConnectionError(SERVER_CLOSED_CONNECTION_ERROR)
redis.exceptions.ConnectionError: Connection closed by server.
[2021-08-12 12:41:38,779: ERROR/MainProcess] consumer: Cannot connect to redis://localhost:6379/1: Error 111 connecting to localhost:6379. Connection refused..
Trying again in 2.00 seconds... (1/100)

[2021-08-12 12:41:38,783: ERROR/MainProcess] consumer: Cannot connect to redis://localhost:6379/1: Error 111 connecting to localhost:6379. Connection refused..
Trying again in 2.00 seconds... (1/100)

[2021-08-12 12:41:38,794: ERROR/MainProcess] consumer: Cannot connect to redis://localhost:6379/1: Error 111 connecting to localhost:6379. Connection refused..
Trying again in 2.00 seconds... (1/100)

[2021-08-12 12:41:38,804: ERROR/MainProcess] consumer: Cannot connect to redis://localhost:6379/1: Error 111 connecting to localhost:6379. Connection refused..
Trying again in 2.00 seconds... (1/100)

[2021-08-12 12:41:38,810: ERROR/MainProcess] consumer: Cannot connect to redis://localhost:6379/1: Error 111 connecting to localhost:6379. Connection refused..
Trying again in 2.00 seconds... (1/100)

[2021-08-12 12:41:38,814: ERROR/MainProcess] consumer: Cannot connect to redis://localhost:6379/1: Error 111 connecting to localhost:6379. Connection refused..
Trying again in 2.00 seconds... (1/100)

[2021-08-12 12:41:40,787: INFO/MainProcess] Connected to redis://localhost:6379/1
[2021-08-12 12:41:40,789: INFO/MainProcess] Connected to redis://localhost:6379/1
[2021-08-12 12:41:40,800: INFO/MainProcess] Connected to redis://localhost:6379/1
[2021-08-12 12:41:40,816: INFO/MainProcess] Connected to redis://localhost:6379/1
[2021-08-12 12:41:40,818: INFO/MainProcess] mingle: searching for neighbors
[2021-08-12 12:41:40,819: INFO/MainProcess] Connected to redis://localhost:6379/1
[2021-08-12 12:41:40,842: INFO/MainProcess] Connected to redis://localhost:6379/1
[2021-08-12 12:41:40,843: INFO/MainProcess] mingle: searching for neighbors
[2021-08-12 12:41:40,848: INFO/MainProcess] mingle: searching for neighbors
[2021-08-12 12:41:40,864: INFO/MainProcess] mingle: searching for neighbors
[2021-08-12 12:41:40,868: INFO/MainProcess] mingle: searching for neighbors
[2021-08-12 12:41:40,874: INFO/MainProcess] mingle: searching for neighbors
[2021-08-12 12:41:41,828: INFO/MainProcess] mingle: all alone
[2021-08-12 12:41:41,854: INFO/MainProcess] mingle: all alone
[2021-08-12 12:41:41,857: INFO/MainProcess] mingle: all alone
[2021-08-12 12:41:41,870: INFO/MainProcess] mingle: all alone
[2021-08-12 12:41:41,894: INFO/MainProcess] mingle: all alone
[2021-08-12 12:41:41,896: INFO/MainProcess] mingle: all alone
[2021-08-12 12:41:51,004: WARNING/MainProcess] consumer: Connection to broker lost. Trying to re-establish the connection...
Traceback (most recent call last):
  File "/home/olcaey/koytola/venv/lib/python3.8/site-packages/celery/worker/consumer/consumer.py", line 318, in start
    blueprint.start(self)
  File "/home/olcaey/koytola/venv/lib/python3.8/site-packages/celery/bootsteps.py", line 119, in start
    step.start(parent)
  File "/home/olcaey/koytola/venv/lib/python3.8/site-packages/celery/worker/consumer/consumer.py", line 599, in start
    c.loop(*c.loop_args())
  File "/home/olcaey/koytola/venv/lib/python3.8/site-packages/celery/worker/loops.py", line 83, in asynloop
    next(loop)
  File "/home/olcaey/koytola/venv/lib/python3.8/site-packages/kombu/asynchronous/hub.py", line 364, in create_loop
    cb(*cbargs)
  File "/home/olcaey/koytola/venv/lib/python3.8/site-packages/kombu/transport/redis.py", line 1083, in on_readable
    self.cycle.on_readable(fileno)
  File "/home/olcaey/koytola/venv/lib/python3.8/site-packages/kombu/transport/redis.py", line 354, in on_readable
    chan.handlers[type]()
  File "/home/olcaey/koytola/venv/lib/python3.8/site-packages/kombu/transport/redis.py", line 688, in _receive
    ret.append(self._receive_one(c))
  File "/home/olcaey/koytola/venv/lib/python3.8/site-packages/kombu/transport/redis.py", line 698, in _receive_one
    response = c.parse_response()
  File "/home/olcaey/koytola/venv/lib/python3.8/site-packages/redis/client.py", line 3505, in parse_response
    response = self._execute(conn, conn.read_response)
  File "/home/olcaey/koytola/venv/lib/python3.8/site-packages/redis/client.py", line 3479, in _execute
    return command(*args, **kwargs)
  File "/home/olcaey/koytola/venv/lib/python3.8/site-packages/redis/connection.py", line 739, in read_response
    response = self._parser.read_response()
  File "/home/olcaey/koytola/venv/lib/python3.8/site-packages/redis/connection.py", line 324, in read_response
    raw = self._buffer.readline()
  File "/home/olcaey/koytola/venv/lib/python3.8/site-packages/redis/connection.py", line 256, in readline
    self._read_from_socket()
  File "/home/olcaey/koytola/venv/lib/python3.8/site-packages/redis/connection.py", line 201, in _read_from_socket
    raise ConnectionError(SERVER_CLOSED_CONNECTION_ERROR)
redis.exceptions.ConnectionError: Connection closed by server.
[2021-08-12 12:41:51,004: WARNING/MainProcess] consumer: Connection to broker lost. Trying to re-establish the connection...
Traceback (most recent call last):
  File "/home/olcaey/koytola/venv/lib/python3.8/site-packages/celery/worker/consumer/consumer.py", line 318, in start
    blueprint.start(self)
  File "/home/olcaey/koytola/venv/lib/python3.8/site-packages/celery/bootsteps.py", line 119, in start
    step.start(parent)
  File "/home/olcaey/koytola/venv/lib/python3.8/site-packages/celery/worker/consumer/consumer.py", line 599, in start
    c.loop(*c.loop_args())
  File "/home/olcaey/koytola/venv/lib/python3.8/site-packages/celery/worker/loops.py", line 83, in asynloop
    next(loop)
  File "/home/olcaey/koytola/venv/lib/python3.8/site-packages/kombu/asynchronous/hub.py", line 364, in create_loop
    cb(*cbargs)
  File "/home/olcaey/koytola/venv/lib/python3.8/site-packages/kombu/transport/redis.py", line 1083, in on_readable
    self.cycle.on_readable(fileno)
  File "/home/olcaey/koytola/venv/lib/python3.8/site-packages/kombu/transport/redis.py", line 354, in on_readable
    chan.handlers[type]()
  File "/home/olcaey/koytola/venv/lib/python3.8/site-packages/kombu/transport/redis.py", line 688, in _receive
    ret.append(self._receive_one(c))
  File "/home/olcaey/koytola/venv/lib/python3.8/site-packages/kombu/transport/redis.py", line 698, in _receive_one
    response = c.parse_response()
  File "/home/olcaey/koytola/venv/lib/python3.8/site-packages/redis/client.py", line 3505, in parse_response
    response = self._execute(conn, conn.read_response)
  File "/home/olcaey/koytola/venv/lib/python3.8/site-packages/redis/client.py", line 3479, in _execute
    return command(*args, **kwargs)
  File "/home/olcaey/koytola/venv/lib/python3.8/site-packages/redis/connection.py", line 739, in read_response
    response = self._parser.read_response()
  File "/home/olcaey/koytola/venv/lib/python3.8/site-packages/redis/connection.py", line 324, in read_response
    raw = self._buffer.readline()
  File "/home/olcaey/koytola/venv/lib/python3.8/site-packages/redis/connection.py", line 256, in readline
    self._read_from_socket()
  File "/home/olcaey/koytola/venv/lib/python3.8/site-packages/redis/connection.py", line 201, in _read_from_socket
    raise ConnectionError(SERVER_CLOSED_CONNECTION_ERROR)
redis.exceptions.ConnectionError: Connection closed by server.
[2021-08-12 12:41:51,007: WARNING/MainProcess] consumer: Connection to broker lost. Trying to re-establish the connection...
Traceback (most recent call last):
  File "/home/olcaey/koytola/venv/lib/python3.8/site-packages/celery/worker/consumer/consumer.py", line 318, in start
    blueprint.start(self)
  File "/home/olcaey/koytola/venv/lib/python3.8/site-packages/celery/bootsteps.py", line 119, in start
    step.start(parent)
  File "/home/olcaey/koytola/venv/lib/python3.8/site-packages/celery/worker/consumer/consumer.py", line 599, in start
    c.loop(*c.loop_args())
  File "/home/olcaey/koytola/venv/lib/python3.8/site-packages/celery/worker/loops.py", line 83, in asynloop
    next(loop)
  File "/home/olcaey/koytola/venv/lib/python3.8/site-packages/kombu/asynchronous/hub.py", line 364, in create_loop
    cb(*cbargs)
  File "/home/olcaey/koytola/venv/lib/python3.8/site-packages/kombu/transport/redis.py", line 1083, in on_readable
    self.cycle.on_readable(fileno)
  File "/home/olcaey/koytola/venv/lib/python3.8/site-packages/kombu/transport/redis.py", line 354, in on_readable
    chan.handlers[type]()
  File "/home/olcaey/koytola/venv/lib/python3.8/site-packages/kombu/transport/redis.py", line 688, in _receive
    ret.append(self._receive_one(c))
  File "/home/olcaey/koytola/venv/lib/python3.8/site-packages/kombu/transport/redis.py", line 698, in _receive_one
    response = c.parse_response()
  File "/home/olcaey/koytola/venv/lib/python3.8/site-packages/redis/client.py", line 3505, in parse_response
    response = self._execute(conn, conn.read_response)
  File "/home/olcaey/koytola/venv/lib/python3.8/site-packages/redis/client.py", line 3479, in _execute
    return command(*args, **kwargs)
  File "/home/olcaey/koytola/venv/lib/python3.8/site-packages/redis/connection.py", line 739, in read_response
    response = self._parser.read_response()
  File "/home/olcaey/koytola/venv/lib/python3.8/site-packages/redis/connection.py", line 324, in read_response
    raw = self._buffer.readline()
  File "/home/olcaey/koytola/venv/lib/python3.8/site-packages/redis/connection.py", line 256, in readline
    self._read_from_socket()
  File "/home/olcaey/koytola/venv/lib/python3.8/site-packages/redis/connection.py", line 201, in _read_from_socket
    raise ConnectionError(SERVER_CLOSED_CONNECTION_ERROR)
redis.exceptions.ConnectionError: Connection closed by server.
[2021-08-12 12:41:51,010: WARNING/MainProcess] consumer: Connection to broker lost. Trying to re-establish the connection...
Traceback (most recent call last):
  File "/home/olcaey/koytola/venv/lib/python3.8/site-packages/celery/worker/consumer/consumer.py", line 318, in start
    blueprint.start(self)
  File "/home/olcaey/koytola/venv/lib/python3.8/site-packages/celery/bootsteps.py", line 119, in start
    step.start(parent)
  File "/home/olcaey/koytola/venv/lib/python3.8/site-packages/celery/worker/consumer/consumer.py", line 599, in start
    c.loop(*c.loop_args())
  File "/home/olcaey/koytola/venv/lib/python3.8/site-packages/celery/worker/loops.py", line 83, in asynloop
    next(loop)
  File "/home/olcaey/koytola/venv/lib/python3.8/site-packages/kombu/asynchronous/hub.py", line 364, in create_loop
    cb(*cbargs)
  File "/home/olcaey/koytola/venv/lib/python3.8/site-packages/kombu/transport/redis.py", line 1083, in on_readable
    self.cycle.on_readable(fileno)
  File "/home/olcaey/koytola/venv/lib/python3.8/site-packages/kombu/transport/redis.py", line 354, in on_readable
    chan.handlers[type]()
  File "/home/olcaey/koytola/venv/lib/python3.8/site-packages/kombu/transport/redis.py", line 688, in _receive
    ret.append(self._receive_one(c))
  File "/home/olcaey/koytola/venv/lib/python3.8/site-packages/kombu/transport/redis.py", line 698, in _receive_one
    response = c.parse_response()
  File "/home/olcaey/koytola/venv/lib/python3.8/site-packages/redis/client.py", line 3505, in parse_response
    response = self._execute(conn, conn.read_response)
  File "/home/olcaey/koytola/venv/lib/python3.8/site-packages/redis/client.py", line 3479, in _execute
    return command(*args, **kwargs)
  File "/home/olcaey/koytola/venv/lib/python3.8/site-packages/redis/connection.py", line 739, in read_response
    response = self._parser.read_response()
  File "/home/olcaey/koytola/venv/lib/python3.8/site-packages/redis/connection.py", line 324, in read_response
    raw = self._buffer.readline()
  File "/home/olcaey/koytola/venv/lib/python3.8/site-packages/redis/connection.py", line 256, in readline
    self._read_from_socket()
  File "/home/olcaey/koytola/venv/lib/python3.8/site-packages/redis/connection.py", line 201, in _read_from_socket
    raise ConnectionError(SERVER_CLOSED_CONNECTION_ERROR)
redis.exceptions.ConnectionError: Connection closed by server.
[2021-08-12 12:41:51,013: WARNING/MainProcess] consumer: Connection to broker lost. Trying to re-establish the connection...
Traceback (most recent call last):
  File "/home/olcaey/koytola/venv/lib/python3.8/site-packages/celery/worker/consumer/consumer.py", line 318, in start
    blueprint.start(self)
  File "/home/olcaey/koytola/venv/lib/python3.8/site-packages/celery/bootsteps.py", line 119, in start
    step.start(parent)
  File "/home/olcaey/koytola/venv/lib/python3.8/site-packages/celery/worker/consumer/consumer.py", line 599, in start
    c.loop(*c.loop_args())
  File "/home/olcaey/koytola/venv/lib/python3.8/site-packages/celery/worker/loops.py", line 83, in asynloop
    next(loop)
  File "/home/olcaey/koytola/venv/lib/python3.8/site-packages/kombu/asynchronous/hub.py", line 364, in create_loop
    cb(*cbargs)
  File "/home/olcaey/koytola/venv/lib/python3.8/site-packages/kombu/transport/redis.py", line 1083, in on_readable
    self.cycle.on_readable(fileno)
  File "/home/olcaey/koytola/venv/lib/python3.8/site-packages/kombu/transport/redis.py", line 354, in on_readable
    chan.handlers[type]()
  File "/home/olcaey/koytola/venv/lib/python3.8/site-packages/kombu/transport/redis.py", line 688, in _receive
    ret.append(self._receive_one(c))
  File "/home/olcaey/koytola/venv/lib/python3.8/site-packages/kombu/transport/redis.py", line 698, in _receive_one
    response = c.parse_response()
  File "/home/olcaey/koytola/venv/lib/python3.8/site-packages/redis/client.py", line 3505, in parse_response
    response = self._execute(conn, conn.read_response)
  File "/home/olcaey/koytola/venv/lib/python3.8/site-packages/redis/client.py", line 3479, in _execute
    return command(*args, **kwargs)
  File "/home/olcaey/koytola/venv/lib/python3.8/site-packages/redis/connection.py", line 739, in read_response
    response = self._parser.read_response()
  File "/home/olcaey/koytola/venv/lib/python3.8/site-packages/redis/connection.py", line 324, in read_response
    raw = self._buffer.readline()
  File "/home/olcaey/koytola/venv/lib/python3.8/site-packages/redis/connection.py", line 256, in readline
    self._read_from_socket()
  File "/home/olcaey/koytola/venv/lib/python3.8/site-packages/redis/connection.py", line 201, in _read_from_socket
    raise ConnectionError(SERVER_CLOSED_CONNECTION_ERROR)
redis.exceptions.ConnectionError: Connection closed by server.
[2021-08-12 12:41:51,020: WARNING/MainProcess] consumer: Connection to broker lost. Trying to re-establish the connection...
Traceback (most recent call last):
  File "/home/olcaey/koytola/venv/lib/python3.8/site-packages/celery/worker/consumer/consumer.py", line 318, in start
    blueprint.start(self)
  File "/home/olcaey/koytola/venv/lib/python3.8/site-packages/celery/bootsteps.py", line 119, in start
    step.start(parent)
  File "/home/olcaey/koytola/venv/lib/python3.8/site-packages/celery/worker/consumer/consumer.py", line 599, in start
    c.loop(*c.loop_args())
  File "/home/olcaey/koytola/venv/lib/python3.8/site-packages/celery/worker/loops.py", line 83, in asynloop
    next(loop)
  File "/home/olcaey/koytola/venv/lib/python3.8/site-packages/kombu/asynchronous/hub.py", line 364, in create_loop
    cb(*cbargs)
  File "/home/olcaey/koytola/venv/lib/python3.8/site-packages/kombu/transport/redis.py", line 1083, in on_readable
    self.cycle.on_readable(fileno)
  File "/home/olcaey/koytola/venv/lib/python3.8/site-packages/kombu/transport/redis.py", line 354, in on_readable
    chan.handlers[type]()
  File "/home/olcaey/koytola/venv/lib/python3.8/site-packages/kombu/transport/redis.py", line 688, in _receive
    ret.append(self._receive_one(c))
  File "/home/olcaey/koytola/venv/lib/python3.8/site-packages/kombu/transport/redis.py", line 698, in _receive_one
    response = c.parse_response()
  File "/home/olcaey/koytola/venv/lib/python3.8/site-packages/redis/client.py", line 3505, in parse_response
    response = self._execute(conn, conn.read_response)
  File "/home/olcaey/koytola/venv/lib/python3.8/site-packages/redis/client.py", line 3479, in _execute
    return command(*args, **kwargs)
  File "/home/olcaey/koytola/venv/lib/python3.8/site-packages/redis/connection.py", line 739, in read_response
    response = self._parser.read_response()
  File "/home/olcaey/koytola/venv/lib/python3.8/site-packages/redis/connection.py", line 324, in read_response
    raw = self._buffer.readline()
  File "/home/olcaey/koytola/venv/lib/python3.8/site-packages/redis/connection.py", line 256, in readline
    self._read_from_socket()
  File "/home/olcaey/koytola/venv/lib/python3.8/site-packages/redis/connection.py", line 201, in _read_from_socket
    raise ConnectionError(SERVER_CLOSED_CONNECTION_ERROR)
redis.exceptions.ConnectionError: Connection closed by server.
[2021-08-12 12:41:51,090: ERROR/MainProcess] consumer: Cannot connect to redis://localhost:6379/1: Error 111 connecting to localhost:6379. Connection refused..
Trying again in 2.00 seconds... (1/100)

[2021-08-12 12:41:51,103: ERROR/MainProcess] consumer: Cannot connect to redis://localhost:6379/1: Error 111 connecting to localhost:6379. Connection refused..
Trying again in 2.00 seconds... (1/100)

[2021-08-12 12:41:51,105: ERROR/MainProcess] consumer: Cannot connect to redis://localhost:6379/1: Error 111 connecting to localhost:6379. Connection refused..
Trying again in 2.00 seconds... (1/100)

[2021-08-12 12:41:51,107: ERROR/MainProcess] consumer: Cannot connect to redis://localhost:6379/1: Error 111 connecting to localhost:6379. Connection refused..
Trying again in 2.00 seconds... (1/100)

[2021-08-12 12:41:51,109: ERROR/MainProcess] consumer: Cannot connect to redis://localhost:6379/1: Error 111 connecting to localhost:6379. Connection refused..
Trying again in 2.00 seconds... (1/100)

[2021-08-12 12:41:51,096: ERROR/MainProcess] consumer: Cannot connect to redis://localhost:6379/1: Error 111 connecting to localhost:6379. Connection refused..
Trying again in 2.00 seconds... (1/100)

[2021-08-12 12:41:53,096: INFO/MainProcess] Connected to redis://localhost:6379/1
[2021-08-12 12:41:53,122: INFO/MainProcess] Connected to redis://localhost:6379/1
[2021-08-12 12:41:53,127: INFO/MainProcess] mingle: searching for neighbors
[2021-08-12 12:41:53,132: INFO/MainProcess] Connected to redis://localhost:6379/1
[2021-08-12 12:41:53,137: INFO/MainProcess] Connected to redis://localhost:6379/1
[2021-08-12 12:41:53,141: INFO/MainProcess] Connected to redis://localhost:6379/1
[2021-08-12 12:41:53,141: INFO/MainProcess] Connected to redis://localhost:6379/1
[2021-08-12 12:41:53,176: INFO/MainProcess] mingle: searching for neighbors
[2021-08-12 12:41:53,182: INFO/MainProcess] mingle: searching for neighbors
[2021-08-12 12:41:53,198: INFO/MainProcess] mingle: searching for neighbors
[2021-08-12 12:41:53,200: INFO/MainProcess] mingle: searching for neighbors
[2021-08-12 12:41:53,216: INFO/MainProcess] mingle: searching for neighbors
[2021-08-12 12:41:54,175: INFO/MainProcess] mingle: all alone
[2021-08-12 12:41:54,193: INFO/MainProcess] mingle: all alone
[2021-08-12 12:41:54,204: INFO/MainProcess] mingle: all alone
[2021-08-12 12:41:54,215: INFO/MainProcess] mingle: all alone
[2021-08-12 12:41:54,218: INFO/MainProcess] mingle: all alone
[2021-08-12 12:41:54,238: INFO/MainProcess] mingle: all alone
/home/olcaey/koytola/venv/lib/python3.8/site-packages/graphene_django/types.py:94: UserWarning: Field name "description" doesn't exist on Django model "profile.Certificate". Consider removing the field from the "fields" list of DjangoObjectType "Certificate" because it has no effect.
  warnings.warn(
/home/olcaey/koytola/venv/lib/python3.8/site-packages/graphene_django/types.py:94: UserWarning: Field name "name" doesn't exist on Django model "profile.Certificate". Consider removing the field from the "fields" list of DjangoObjectType "Certificate" because it has no effect.
  warnings.warn(
/home/olcaey/koytola/venv/lib/python3.8/site-packages/graphene_django/types.py:94: UserWarning: Field name "content" doesn't exist on Django model "blog.Blog". Consider removing the field from the "fields" list of DjangoObjectType "BlogTranslatableContent" because it has no effect.
  warnings.warn(
/home/olcaey/koytola/venv/lib/python3.8/site-packages/graphene_django/types.py:94: UserWarning: Field name "summary" doesn't exist on Django model "blog.Blog". Consider removing the field from the "fields" list of DjangoObjectType "BlogTranslatableContent" because it has no effect.
  warnings.warn(
/home/olcaey/koytola/venv/lib/python3.8/site-packages/graphene_django/types.py:94: UserWarning: Field name "content_plaintext" doesn't exist on Django model "news.News". Consider removing the field from the "fields" list of DjangoObjectType "NewsTranslatableContent" because it has no effect.
  warnings.warn(
/home/olcaey/koytola/venv/lib/python3.8/site-packages/graphene_django/types.py:94: UserWarning: Field name "description" doesn't exist on Django model "news.News". Consider removing the field from the "fields" list of DjangoObjectType "News" because it has no effect.
  warnings.warn(
[2021-08-12 12:42:25,070: INFO/MainProcess] Connected to redis://localhost:6379/1
[2021-08-12 12:42:25,079: INFO/MainProcess] mingle: searching for neighbors
[2021-08-12 12:42:26,114: WARNING/MainProcess] /home/olcaey/koytola/venv/lib/python3.8/site-packages/celery/app/control.py:52: DuplicateNodenameWarning: Received multiple replies from node name: celery@koytola-dev.
Please make sure you give each node a unique nodename using
the celery worker `-n` option.
  warnings.warn(DuplicateNodenameWarning(
[2021-08-12 12:42:26,115: INFO/MainProcess] mingle: all alone
[2021-08-12 12:42:26,130: INFO/MainProcess] celery@koytola-dev ready.
[2021-08-12 12:44:51,611: INFO/MainProcess] Received task: koytola.account.emails._send_account_confirmation_email[90e1c0a4-1b1f-47e3-97d3-b4b883c294b2]  
[2021-08-12 12:44:53,101: INFO/ForkPoolWorker-1] Task koytola.account.emails._send_account_confirmation_email[90e1c0a4-1b1f-47e3-97d3-b4b883c294b2] succeeded in 1.4838756159879267s: None
/home/olcaey/koytola/venv/lib/python3.8/site-packages/graphene_django/types.py:94: UserWarning: Field name "description" doesn't exist on Django model "profile.Certificate". Consider removing the field from the "fields" list of DjangoObjectType "Certificate" because it has no effect.
  warnings.warn(
/home/olcaey/koytola/venv/lib/python3.8/site-packages/graphene_django/types.py:94: UserWarning: Field name "name" doesn't exist on Django model "profile.Certificate". Consider removing the field from the "fields" list of DjangoObjectType "Certificate" because it has no effect.
  warnings.warn(
/home/olcaey/koytola/venv/lib/python3.8/site-packages/graphene_django/types.py:94: UserWarning: Field name "content" doesn't exist on Django model "blog.Blog". Consider removing the field from the "fields" list of DjangoObjectType "BlogTranslatableContent" because it has no effect.
  warnings.warn(
/home/olcaey/koytola/venv/lib/python3.8/site-packages/graphene_django/types.py:94: UserWarning: Field name "summary" doesn't exist on Django model "blog.Blog". Consider removing the field from the "fields" list of DjangoObjectType "BlogTranslatableContent" because it has no effect.
  warnings.warn(
/home/olcaey/koytola/venv/lib/python3.8/site-packages/graphene_django/types.py:94: UserWarning: Field name "content_plaintext" doesn't exist on Django model "news.News". Consider removing the field from the "fields" list of DjangoObjectType "NewsTranslatableContent" because it has no effect.
  warnings.warn(
/home/olcaey/koytola/venv/lib/python3.8/site-packages/graphene_django/types.py:94: UserWarning: Field name "description" doesn't exist on Django model "news.News". Consider removing the field from the "fields" list of DjangoObjectType "News" because it has no effect.
  warnings.warn(
[2021-08-12 13:02:58,642: INFO/MainProcess] Connected to redis://localhost:6379/1
[2021-08-12 13:02:58,651: INFO/MainProcess] mingle: searching for neighbors
[2021-08-12 13:02:59,685: WARNING/MainProcess] /home/olcaey/koytola/venv/lib/python3.8/site-packages/celery/app/control.py:52: DuplicateNodenameWarning: Received multiple replies from node name: celery@koytola-dev.
Please make sure you give each node a unique nodename using
the celery worker `-n` option.
  warnings.warn(DuplicateNodenameWarning(
[2021-08-12 13:02:59,685: INFO/MainProcess] mingle: all alone
[2021-08-12 13:02:59,701: INFO/MainProcess] celery@koytola-dev ready.
[2021-08-13 05:31:14,846: INFO/MainProcess] Received task: koytola.account.emails._send_account_confirmation_email[28c4b678-d1f2-4b7a-ad69-fd0c3728cd31]  
[2021-08-13 05:31:16,265: INFO/ForkPoolWorker-1] Task koytola.account.emails._send_account_confirmation_email[28c4b678-d1f2-4b7a-ad69-fd0c3728cd31] succeeded in 1.4069653460755944s: None
[2021-08-13 11:51:05,418: INFO/MainProcess] Received task: koytola.account.emails._send_account_confirmation_email[a16666d4-f9cd-4e7f-9913-6b2c1a9480b3]  
/home/olcaey/koytola/venv/lib/python3.8/site-packages/graphene_django/types.py:94: UserWarning: Field name "description" doesn't exist on Django model "profile.Certificate". Consider removing the field from the "fields" list of DjangoObjectType "Certificate" because it has no effect.
  warnings.warn(
/home/olcaey/koytola/venv/lib/python3.8/site-packages/graphene_django/types.py:94: UserWarning: Field name "name" doesn't exist on Django model "profile.Certificate". Consider removing the field from the "fields" list of DjangoObjectType "Certificate" because it has no effect.
  warnings.warn(
/home/olcaey/koytola/venv/lib/python3.8/site-packages/graphene_django/types.py:94: UserWarning: Field name "content" doesn't exist on Django model "blog.Blog". Consider removing the field from the "fields" list of DjangoObjectType "BlogTranslatableContent" because it has no effect.
  warnings.warn(
/home/olcaey/koytola/venv/lib/python3.8/site-packages/graphene_django/types.py:94: UserWarning: Field name "summary" doesn't exist on Django model "blog.Blog". Consider removing the field from the "fields" list of DjangoObjectType "BlogTranslatableContent" because it has no effect.
  warnings.warn(
/home/olcaey/koytola/venv/lib/python3.8/site-packages/graphene_django/types.py:94: UserWarning: Field name "content_plaintext" doesn't exist on Django model "news.News". Consider removing the field from the "fields" list of DjangoObjectType "NewsTranslatableContent" because it has no effect.
  warnings.warn(
/home/olcaey/koytola/venv/lib/python3.8/site-packages/graphene_django/types.py:94: UserWarning: Field name "description" doesn't exist on Django model "news.News". Consider removing the field from the "fields" list of DjangoObjectType "News" because it has no effect.
  warnings.warn(
[2021-08-13 11:51:06,584: INFO/ForkPoolWorker-1] Task koytola.account.emails._send_account_confirmation_email[a16666d4-f9cd-4e7f-9913-6b2c1a9480b3] succeeded in 1.151692371815443s: None
[2021-08-16 06:05:46,862: INFO/MainProcess] Received task: koytola.account.emails._send_account_confirmation_email[c34a5d82-8b99-443a-8487-3417ed4f731a]  
[2021-08-16 06:05:48,358: INFO/ForkPoolWorker-1] Task koytola.account.emails._send_account_confirmation_email[c34a5d82-8b99-443a-8487-3417ed4f731a] succeeded in 1.4829687443561852s: None
[2021-08-16 07:21:51,030: INFO/MainProcess] Received task: koytola.account.emails._send_password_reset_email_with_url[84df0375-8486-4a20-989c-1bfa86dffc8e]  
[2021-08-16 07:21:51,084: INFO/MainProcess] Received task: koytola.account.emails._send_password_reset_email_with_url[80bc8352-25d9-448a-96d1-c8ec98092fd7]  
[2021-08-16 07:21:52,353: INFO/ForkPoolWorker-1] Task koytola.account.emails._send_password_reset_email_with_url[84df0375-8486-4a20-989c-1bfa86dffc8e] succeeded in 1.3190769092179835s: None
[2021-08-16 07:21:52,437: INFO/ForkPoolWorker-1] Task koytola.account.emails._send_password_reset_email_with_url[80bc8352-25d9-448a-96d1-c8ec98092fd7] succeeded in 1.350280815269798s: None
[2021-08-16 07:22:17,231: INFO/MainProcess] Received task: koytola.account.emails._send_password_reset_email_with_url[048789e4-0e98-4f0d-9f55-10780c300ef0]  
[2021-08-16 07:22:17,297: INFO/MainProcess] Received task: koytola.account.emails._send_password_reset_email_with_url[1eecadaa-3a08-4fca-b7ff-fe7305d8cbbe]  
[2021-08-16 07:22:18,134: INFO/ForkPoolWorker-1] Task koytola.account.emails._send_password_reset_email_with_url[048789e4-0e98-4f0d-9f55-10780c300ef0] succeeded in 0.9017477910965681s: None
/home/olcaey/koytola/venv/lib/python3.8/site-packages/graphene_django/types.py:94: UserWarning: Field name "description" doesn't exist on Django model "profile.Certificate". Consider removing the field from the "fields" list of DjangoObjectType "Certificate" because it has no effect.
  warnings.warn(
/home/olcaey/koytola/venv/lib/python3.8/site-packages/graphene_django/types.py:94: UserWarning: Field name "name" doesn't exist on Django model "profile.Certificate". Consider removing the field from the "fields" list of DjangoObjectType "Certificate" because it has no effect.
  warnings.warn(
/home/olcaey/koytola/venv/lib/python3.8/site-packages/graphene_django/types.py:94: UserWarning: Field name "content" doesn't exist on Django model "blog.Blog". Consider removing the field from the "fields" list of DjangoObjectType "BlogTranslatableContent" because it has no effect.
  warnings.warn(
/home/olcaey/koytola/venv/lib/python3.8/site-packages/graphene_django/types.py:94: UserWarning: Field name "summary" doesn't exist on Django model "blog.Blog". Consider removing the field from the "fields" list of DjangoObjectType "BlogTranslatableContent" because it has no effect.
  warnings.warn(
/home/olcaey/koytola/venv/lib/python3.8/site-packages/graphene_django/types.py:94: UserWarning: Field name "content_plaintext" doesn't exist on Django model "news.News". Consider removing the field from the "fields" list of DjangoObjectType "NewsTranslatableContent" because it has no effect.
  warnings.warn(
/home/olcaey/koytola/venv/lib/python3.8/site-packages/graphene_django/types.py:94: UserWarning: Field name "description" doesn't exist on Django model "news.News". Consider removing the field from the "fields" list of DjangoObjectType "News" because it has no effect.
  warnings.warn(
[2021-08-16 07:22:18,250: INFO/ForkPoolWorker-1] Task koytola.account.emails._send_password_reset_email_with_url[1eecadaa-3a08-4fca-b7ff-fe7305d8cbbe] succeeded in 0.9495968269184232s: None
[2021-08-16 07:58:09,371: INFO/MainProcess] Received task: koytola.account.emails._send_password_reset_email_with_url[f35078b0-e2cd-450c-a197-85d2e0f5b01b]  
[2021-08-16 07:58:10,479: INFO/ForkPoolWorker-1] Task koytola.account.emails._send_password_reset_email_with_url[f35078b0-e2cd-450c-a197-85d2e0f5b01b] succeeded in 1.096344109158963s: None
[2021-08-16 08:07:47,393: INFO/MainProcess] Received task: koytola.account.emails._send_account_confirmation_email[d9241e2f-d58f-49e7-9ce4-2e108da3f1c0]  
[2021-08-16 08:07:48,686: INFO/ForkPoolWorker-1] Task koytola.account.emails._send_account_confirmation_email[d9241e2f-d58f-49e7-9ce4-2e108da3f1c0] succeeded in 1.2905100560747087s: None
[2021-08-16 08:47:34,312: INFO/MainProcess] Received task: koytola.account.emails._send_password_reset_email_with_url[fbf0b34d-86df-4c49-8342-b5b163ca4765]  
[2021-08-16 08:47:34,365: INFO/MainProcess] Received task: koytola.account.emails._send_password_reset_email_with_url[59fa2114-1075-4cac-9e6a-21756507b26c]  
[2021-08-16 08:47:35,974: INFO/ForkPoolWorker-1] Task koytola.account.emails._send_password_reset_email_with_url[fbf0b34d-86df-4c49-8342-b5b163ca4765] succeeded in 1.6599510130472481s: None
[2021-08-16 08:47:36,181: INFO/ForkPoolWorker-1] Task koytola.account.emails._send_password_reset_email_with_url[59fa2114-1075-4cac-9e6a-21756507b26c] succeeded in 1.7981829629279673s: None
[2021-08-16 09:00:35,678: INFO/MainProcess] Received task: koytola.account.emails._send_password_reset_email_with_url[ffbcf5af-e1a6-41f8-8c30-eca4b2cd187e]  
[2021-08-16 09:00:35,717: INFO/MainProcess] Received task: koytola.account.emails._send_password_reset_email_with_url[14b1ee84-a618-42b5-ae0d-c57066451095]  
[2021-08-16 09:00:36,935: INFO/ForkPoolWorker-1] Task koytola.account.emails._send_password_reset_email_with_url[14b1ee84-a618-42b5-ae0d-c57066451095] succeeded in 1.2157439631409943s: None
[2021-08-16 09:00:37,070: INFO/ForkPoolWorker-1] Task koytola.account.emails._send_password_reset_email_with_url[ffbcf5af-e1a6-41f8-8c30-eca4b2cd187e] succeeded in 1.3889851379208267s: None
[2021-08-16 09:06:57,674: INFO/MainProcess] Received task: koytola.account.emails._send_password_reset_email_with_url[21e9a26b-f22a-481f-b5b1-3b553dc1c72c]  
[2021-08-16 09:06:57,687: INFO/MainProcess] Received task: koytola.account.emails._send_password_reset_email_with_url[6ab7711e-58a9-4d06-9c26-1d9aff3b6ebd]  
[2021-08-16 09:06:58,702: INFO/ForkPoolWorker-1] Task koytola.account.emails._send_password_reset_email_with_url[21e9a26b-f22a-481f-b5b1-3b553dc1c72c] succeeded in 1.0261658779345453s: None
[2021-08-16 09:06:58,815: INFO/ForkPoolWorker-1] Task koytola.account.emails._send_password_reset_email_with_url[6ab7711e-58a9-4d06-9c26-1d9aff3b6ebd] succeeded in 1.126498743891716s: None
[2021-08-16 09:43:15,956: INFO/MainProcess] Received task: koytola.account.emails._send_account_confirmation_email[fa185b72-3455-4a81-a157-198f4633a777]  
[2021-08-16 09:43:17,255: INFO/ForkPoolWorker-1] Task koytola.account.emails._send_account_confirmation_email[fa185b72-3455-4a81-a157-198f4633a777] succeeded in 1.2911505470983684s: None
[2021-08-16 10:06:34,750: INFO/MainProcess] Received task: koytola.account.emails._send_account_confirmation_email[f4007c27-b993-4e07-99da-be1e672d903c]  
[2021-08-16 10:06:35,906: INFO/ForkPoolWorker-1] Task koytola.account.emails._send_account_confirmation_email[f4007c27-b993-4e07-99da-be1e672d903c] succeeded in 1.152314190287143s: None
[2021-08-16 10:08:28,895: INFO/MainProcess] Received task: koytola.account.emails._send_password_reset_email_with_url[af42ef09-7477-43c4-92fa-ad36e4bcddba]  
[2021-08-16 10:08:28,906: INFO/MainProcess] Received task: koytola.account.emails._send_password_reset_email_with_url[4dddebfb-52fe-4f34-9d20-c72d82f54120]  
[2021-08-16 10:08:29,906: INFO/ForkPoolWorker-1] Task koytola.account.emails._send_password_reset_email_with_url[4dddebfb-52fe-4f34-9d20-c72d82f54120] succeeded in 0.9977062018588185s: None
[2021-08-16 10:08:30,074: INFO/ForkPoolWorker-1] Task koytola.account.emails._send_password_reset_email_with_url[af42ef09-7477-43c4-92fa-ad36e4bcddba] succeeded in 1.1771462797187269s: None
[2021-08-17 05:30:48,312: INFO/MainProcess] Received task: koytola.account.emails._send_password_reset_email_with_url[c6d8c656-4e81-44ba-8c34-ae3e1312ff59]  
[2021-08-17 05:30:48,316: INFO/MainProcess] Received task: koytola.account.emails._send_password_reset_email_with_url[856506a0-2f7d-4111-90af-ba7969d03ae5]  
[2021-08-17 05:30:50,650: INFO/ForkPoolWorker-1] Task koytola.account.emails._send_password_reset_email_with_url[c6d8c656-4e81-44ba-8c34-ae3e1312ff59] succeeded in 2.335172249004245s: None
[2021-08-17 05:30:50,845: INFO/ForkPoolWorker-1] Task koytola.account.emails._send_password_reset_email_with_url[856506a0-2f7d-4111-90af-ba7969d03ae5] succeeded in 2.527984776068479s: None
[2021-08-17 09:40:19,021: INFO/MainProcess] Received task: koytola.account.emails._send_account_confirmation_email[b1b25491-b3e0-4a22-957e-292bcff02abd]  
[2021-08-17 09:40:20,583: INFO/ForkPoolWorker-1] Task koytola.account.emails._send_account_confirmation_email[b1b25491-b3e0-4a22-957e-292bcff02abd] succeeded in 1.5611882442608476s: None
[2021-08-17 13:41:58,662: INFO/MainProcess] Received task: koytola.account.emails._send_account_confirmation_email[5c52fdf0-c48d-46b9-a351-6dafda792e2f]  
[2021-08-17 13:41:59,719: INFO/ForkPoolWorker-1] Task koytola.account.emails._send_account_confirmation_email[5c52fdf0-c48d-46b9-a351-6dafda792e2f] succeeded in 1.0557443760335445s: None
[2021-08-18 01:32:24,820: INFO/MainProcess] Received task: koytola.account.emails._send_account_confirmation_email[72ee7556-7c78-4f90-ba4e-6d500ecc533b]  
[2021-08-18 01:32:26,723: INFO/ForkPoolWorker-1] Task koytola.account.emails._send_account_confirmation_email[72ee7556-7c78-4f90-ba4e-6d500ecc533b] succeeded in 1.9008816150017083s: None
[2021-08-18 02:00:39,520: INFO/MainProcess] Received task: koytola.account.emails._send_account_confirmation_email[0e7baf83-6005-4252-9227-93c187b62afd]  
[2021-08-18 02:00:40,901: INFO/ForkPoolWorker-1] Task koytola.account.emails._send_account_confirmation_email[0e7baf83-6005-4252-9227-93c187b62afd] succeeded in 1.3790692980401218s: None
[2021-08-18 02:01:49,030: INFO/MainProcess] Received task: koytola.account.emails._send_account_confirmation_email[605b50c6-b18f-462d-b10b-c5095349ba4f]  
[2021-08-18 02:01:49,924: INFO/ForkPoolWorker-1] Task koytola.account.emails._send_account_confirmation_email[605b50c6-b18f-462d-b10b-c5095349ba4f] succeeded in 0.8900926178321242s: None
[2021-08-18 02:03:04,887: INFO/MainProcess] Received task: koytola.account.emails._send_account_confirmation_email[f532276b-b844-4260-aa2b-8adaf00c7af2]  
[2021-08-18 02:03:05,924: INFO/ForkPoolWorker-1] Task koytola.account.emails._send_account_confirmation_email[f532276b-b844-4260-aa2b-8adaf00c7af2] succeeded in 1.0356094338931143s: None
[2021-08-18 05:15:35,652: INFO/MainProcess] Received task: koytola.account.emails._send_password_reset_email_with_url[b332fec8-50d8-4b8e-aeea-60e36770e89b]  
[2021-08-18 05:15:35,667: INFO/MainProcess] Received task: koytola.account.emails._send_password_reset_email_with_url[643840b5-0745-40fc-b1d8-e7f283120626]  
[2021-08-18 05:15:37,170: INFO/ForkPoolWorker-1] Task koytola.account.emails._send_password_reset_email_with_url[643840b5-0745-40fc-b1d8-e7f283120626] succeeded in 1.5016864240169525s: None
[2021-08-18 05:15:37,284: INFO/ForkPoolWorker-1] Task koytola.account.emails._send_password_reset_email_with_url[b332fec8-50d8-4b8e-aeea-60e36770e89b] succeeded in 1.6292198388837278s: None
[2021-08-18 07:08:31,405: INFO/MainProcess] Received task: koytola.account.emails._send_account_confirmation_email[e307fa98-b4c8-4833-a821-45cf329d6db1]  
[2021-08-18 07:08:33,673: INFO/ForkPoolWorker-1] Task koytola.account.emails._send_account_confirmation_email[e307fa98-b4c8-4833-a821-45cf329d6db1] succeeded in 2.26658972306177s: None
[2021-08-18 07:34:00,774: INFO/MainProcess] Received task: koytola.account.emails._send_account_confirmation_email[e16d9337-4c74-4e67-bda3-317d045cb069]  
[2021-08-18 07:34:02,330: INFO/ForkPoolWorker-1] Task koytola.account.emails._send_account_confirmation_email[e16d9337-4c74-4e67-bda3-317d045cb069] succeeded in 1.5544666340574622s: None
[2021-08-18 08:58:50,256: INFO/MainProcess] Received task: koytola.account.emails._send_account_confirmation_email[a1464247-8059-4227-a699-2fa220747923]  
[2021-08-18 08:58:52,048: INFO/ForkPoolWorker-1] Task koytola.account.emails._send_account_confirmation_email[a1464247-8059-4227-a699-2fa220747923] succeeded in 1.7897289670072496s: None
[2021-08-18 12:00:00,361: INFO/MainProcess] Received task: koytola.account.emails._send_account_confirmation_email[6f348696-3080-4dbc-9291-b328170ca7cf]  
[2021-08-18 12:00:01,548: INFO/ForkPoolWorker-1] Task koytola.account.emails._send_account_confirmation_email[6f348696-3080-4dbc-9291-b328170ca7cf] succeeded in 1.1860858392901719s: None
[2021-08-18 12:03:15,796: INFO/MainProcess] Received task: koytola.account.emails._send_account_confirmation_email[26ef9ce0-b9ce-4509-8ebb-209e543399e7]  
[2021-08-18 12:03:16,823: INFO/ForkPoolWorker-1] Task koytola.account.emails._send_account_confirmation_email[26ef9ce0-b9ce-4509-8ebb-209e543399e7] succeeded in 1.026258995756507s: None
[2021-08-19 04:28:27,411: INFO/MainProcess] Received task: koytola.account.emails._send_account_confirmation_email[f2fbf970-ca54-4f70-a764-5ad131fb74df]  
[2021-08-19 04:28:29,043: INFO/ForkPoolWorker-1] Task koytola.account.emails._send_account_confirmation_email[f2fbf970-ca54-4f70-a764-5ad131fb74df] succeeded in 1.6288681151345372s: None
[2021-08-19 04:49:08,544: INFO/MainProcess] Received task: koytola.account.emails._send_account_confirmation_email[1abcbdb3-f520-4a8b-87e0-00cf8cda9625]  
[2021-08-19 04:49:09,966: INFO/ForkPoolWorker-1] Task koytola.account.emails._send_account_confirmation_email[1abcbdb3-f520-4a8b-87e0-00cf8cda9625] succeeded in 1.4178803977556527s: None
[2021-08-19 05:05:32,948: INFO/MainProcess] Received task: koytola.account.emails._send_account_confirmation_email[8413211b-8e18-4278-be36-b03c1e902223]  
[2021-08-19 05:05:34,175: INFO/ForkPoolWorker-1] Task koytola.account.emails._send_account_confirmation_email[8413211b-8e18-4278-be36-b03c1e902223] succeeded in 1.2234334633685648s: None
[2021-08-19 07:13:35,007: INFO/MainProcess] Received task: koytola.account.emails._send_account_confirmation_email[f8e0196f-172c-4c46-8461-605fa80fa8b1]  
[2021-08-19 07:13:36,787: INFO/ForkPoolWorker-1] Task koytola.account.emails._send_account_confirmation_email[f8e0196f-172c-4c46-8461-605fa80fa8b1] succeeded in 1.7791247279383242s: None
[2021-08-19 07:20:35,391: INFO/MainProcess] Received task: koytola.account.emails._send_account_confirmation_email[239bda6a-c6e9-41d7-bbb3-4de746ffb551]  
[2021-08-19 07:20:36,614: INFO/ForkPoolWorker-1] Task koytola.account.emails._send_account_confirmation_email[239bda6a-c6e9-41d7-bbb3-4de746ffb551] succeeded in 1.2213988238945603s: None
[2021-08-19 07:25:05,647: INFO/MainProcess] Received task: koytola.account.emails._send_account_confirmation_email[1c078291-e6cf-44a1-acab-fea150a6c7a7]  
[2021-08-19 07:25:06,681: INFO/ForkPoolWorker-1] Task koytola.account.emails._send_account_confirmation_email[1c078291-e6cf-44a1-acab-fea150a6c7a7] succeeded in 1.032381375785917s: None
[2021-08-19 09:07:22,850: INFO/MainProcess] Received task: koytola.account.emails._send_account_confirmation_email[92aaf4ed-2d48-4019-a944-bf65c76be296]  
[2021-08-19 09:07:24,023: INFO/ForkPoolWorker-1] Task koytola.account.emails._send_account_confirmation_email[92aaf4ed-2d48-4019-a944-bf65c76be296] succeeded in 1.1718180123716593s: None
[2021-08-19 09:47:12,761: INFO/MainProcess] Received task: koytola.account.emails._send_account_confirmation_email[8b1afb93-434b-4984-9190-0e18d6bfbfc8]  
[2021-08-19 09:47:14,051: INFO/ForkPoolWorker-1] Task koytola.account.emails._send_account_confirmation_email[8b1afb93-434b-4984-9190-0e18d6bfbfc8] succeeded in 1.2880956381559372s: None
[2021-08-19 11:23:41,982: INFO/MainProcess] Received task: koytola.account.emails._send_account_confirmation_email[1db9002a-094f-4a3a-beeb-dd5d7e2303ef]  
[2021-08-19 11:23:43,393: INFO/ForkPoolWorker-1] Task koytola.account.emails._send_account_confirmation_email[1db9002a-094f-4a3a-beeb-dd5d7e2303ef] succeeded in 1.4061709740199149s: None
[2021-08-19 11:24:39,264: INFO/MainProcess] Received task: koytola.account.emails._send_password_reset_email_with_url[bd980e93-feb5-41e2-9988-306043b4be84]  
[2021-08-19 11:24:40,438: INFO/ForkPoolWorker-1] Task koytola.account.emails._send_password_reset_email_with_url[bd980e93-feb5-41e2-9988-306043b4be84] succeeded in 1.17299444694072s: None
[2021-08-19 12:34:46,117: INFO/MainProcess] Received task: koytola.account.emails._send_account_confirmation_email[744bada4-3d78-4591-87bd-c5af65783d54]  
[2021-08-19 12:34:47,105: INFO/ForkPoolWorker-1] Task koytola.account.emails._send_account_confirmation_email[744bada4-3d78-4591-87bd-c5af65783d54] succeeded in 0.9874777691438794s: None
[2021-08-20 09:09:12,679: INFO/MainProcess] Received task: koytola.account.emails._send_account_confirmation_email[90d875eb-f3da-480d-a86b-41991a9a8498]  
[2021-08-20 09:09:14,846: INFO/ForkPoolWorker-1] Task koytola.account.emails._send_account_confirmation_email[90d875eb-f3da-480d-a86b-41991a9a8498] succeeded in 2.164982377551496s: None
[2021-08-20 09:12:09,906: INFO/MainProcess] Received task: koytola.account.emails._send_account_confirmation_email[74f41e01-7b45-45b8-9b71-650efa678101]  
[2021-08-20 09:12:10,839: INFO/ForkPoolWorker-1] Task koytola.account.emails._send_account_confirmation_email[74f41e01-7b45-45b8-9b71-650efa678101] succeeded in 0.9321243218146265s: None
[2021-08-23 09:41:20,166: INFO/MainProcess] Received task: koytola.account.emails._send_account_confirmation_email[9024b877-0757-4641-b88c-174c119c405c]  
[2021-08-23 09:41:21,619: INFO/ForkPoolWorker-1] Task koytola.account.emails._send_account_confirmation_email[9024b877-0757-4641-b88c-174c119c405c] succeeded in 1.4470094135031104s: None
[2021-08-24 06:20:15,451: INFO/MainProcess] Received task: koytola.account.emails._send_account_confirmation_email[83a28f17-f77f-4bb7-a5c7-4219dd08eb44]  
[2021-08-24 06:20:17,002: INFO/ForkPoolWorker-1] Task koytola.account.emails._send_account_confirmation_email[83a28f17-f77f-4bb7-a5c7-4219dd08eb44] succeeded in 1.5432551028206944s: None
[2021-08-24 13:20:01,964: INFO/MainProcess] Received task: koytola.account.emails._send_account_confirmation_email[3f94a40f-d3ac-4e50-b4ae-1add403298a2]  
[2021-08-24 13:20:03,697: INFO/ForkPoolWorker-1] Task koytola.account.emails._send_account_confirmation_email[3f94a40f-d3ac-4e50-b4ae-1add403298a2] succeeded in 1.7296671317890286s: None
[2021-08-24 14:44:49,209: INFO/MainProcess] Received task: koytola.account.emails._send_account_confirmation_email[e5ee2285-e0f1-4e54-80f2-62e95671ed11]  
[2021-08-24 14:44:50,747: INFO/ForkPoolWorker-1] Task koytola.account.emails._send_account_confirmation_email[e5ee2285-e0f1-4e54-80f2-62e95671ed11] succeeded in 1.5303910439833999s: None
[2021-08-24 14:44:55,535: INFO/MainProcess] Received task: koytola.account.emails._send_account_confirmation_email[f4e5f61e-f4f1-40d1-9c20-d6e6ef20568c]  
[2021-08-24 14:44:56,509: INFO/ForkPoolWorker-1] Task koytola.account.emails._send_account_confirmation_email[f4e5f61e-f4f1-40d1-9c20-d6e6ef20568c] succeeded in 0.9668061500415206s: None
[2021-08-25 04:34:39,621: INFO/MainProcess] Received task: koytola.account.emails._send_account_confirmation_email[c1490af5-6d91-4b61-ba94-26308c025fef]  
[2021-08-25 04:34:41,309: INFO/ForkPoolWorker-1] Task koytola.account.emails._send_account_confirmation_email[c1490af5-6d91-4b61-ba94-26308c025fef] succeeded in 1.679977796971798s: None
[2021-08-25 04:47:13,958: INFO/MainProcess] Received task: koytola.account.emails._send_account_confirmation_email[fa67b7f1-a8e4-4717-b9ad-4c64bc89ddb5]  
[2021-08-25 04:47:15,006: INFO/ForkPoolWorker-1] Task koytola.account.emails._send_account_confirmation_email[fa67b7f1-a8e4-4717-b9ad-4c64bc89ddb5] succeeded in 1.0444278037175536s: None
[2021-08-25 05:16:51,108: INFO/MainProcess] Received task: koytola.account.emails._send_account_confirmation_email[99dd6ef0-8d75-4201-aeb7-c7c099f26719]  
[2021-08-25 05:16:52,126: INFO/ForkPoolWorker-1] Task koytola.account.emails._send_account_confirmation_email[99dd6ef0-8d75-4201-aeb7-c7c099f26719] succeeded in 1.0168031007051468s: None
[2021-08-25 05:58:03,482: INFO/MainProcess] Received task: koytola.account.emails._send_account_confirmation_email[c8dff1d6-33fd-4490-a373-7272e21f761a]  
[2021-08-25 05:58:04,934: INFO/ForkPoolWorker-1] Task koytola.account.emails._send_account_confirmation_email[c8dff1d6-33fd-4490-a373-7272e21f761a] succeeded in 1.450848013162613s: None
[2021-08-25 06:11:58,852: INFO/MainProcess] Received task: koytola.account.emails._send_account_confirmation_email[0718cf66-6098-42db-b99e-649a9b2b56ca]  
[2021-08-25 06:12:00,233: INFO/ForkPoolWorker-1] Task koytola.account.emails._send_account_confirmation_email[0718cf66-6098-42db-b99e-649a9b2b56ca] succeeded in 1.379904649220407s: None
[2021-08-25 06:45:44,367: INFO/MainProcess] Received task: koytola.account.emails._send_account_confirmation_email[1e805092-e545-4490-b13b-07a4132795cb]  
[2021-08-25 06:45:46,864: INFO/ForkPoolWorker-1] Task koytola.account.emails._send_account_confirmation_email[1e805092-e545-4490-b13b-07a4132795cb] succeeded in 2.491435406729579s: None
[2021-08-25 12:12:48,587: INFO/MainProcess] Received task: koytola.account.emails._send_account_confirmation_email[a223f632-d40b-4521-9be0-d704cad2bb5f]  
[2021-08-25 12:12:50,228: INFO/ForkPoolWorker-1] Task koytola.account.emails._send_account_confirmation_email[a223f632-d40b-4521-9be0-d704cad2bb5f] succeeded in 1.6362062226980925s: None
[2021-08-26 07:31:06,959: INFO/MainProcess] Received task: koytola.account.emails._send_account_confirmation_email[12aaee81-f2c1-473a-89f7-242cf8297695]  
[2021-08-26 07:31:08,572: INFO/ForkPoolWorker-1] Task koytola.account.emails._send_account_confirmation_email[12aaee81-f2c1-473a-89f7-242cf8297695] succeeded in 1.6042865328490734s: None
[2021-08-26 08:09:03,716: INFO/MainProcess] Received task: koytola.account.emails._send_account_confirmation_email[cc749a2d-f7ea-41dc-9b98-e9acbb02e457]  
[2021-08-26 08:09:05,451: INFO/ForkPoolWorker-1] Task koytola.account.emails._send_account_confirmation_email[cc749a2d-f7ea-41dc-9b98-e9acbb02e457] succeeded in 1.7334025353193283s: None
[2021-08-27 12:56:48,488: INFO/MainProcess] Received task: koytola.account.emails._send_account_confirmation_email[1b851cfa-b326-4ffd-9569-1d0f5410dffd]  
[2021-08-27 12:56:51,064: INFO/ForkPoolWorker-1] Task koytola.account.emails._send_account_confirmation_email[1b851cfa-b326-4ffd-9569-1d0f5410dffd] succeeded in 2.569308504462242s: None
[2021-08-27 12:59:47,838: INFO/MainProcess] Received task: koytola.account.emails._send_account_confirmation_email[c1c1a1ef-c3f9-4359-a85a-74c02a81ef9d]  
[2021-08-27 12:59:48,818: INFO/ForkPoolWorker-1] Task koytola.account.emails._send_account_confirmation_email[c1c1a1ef-c3f9-4359-a85a-74c02a81ef9d] succeeded in 0.978542871773243s: None
[2021-08-27 13:36:39,798: INFO/MainProcess] Received task: koytola.account.emails._send_account_confirmation_email[2d49950d-a46f-4e69-b438-558bb89bf20f]  
[2021-08-27 13:36:41,609: INFO/ForkPoolWorker-1] Task koytola.account.emails._send_account_confirmation_email[2d49950d-a46f-4e69-b438-558bb89bf20f] succeeded in 1.808607142418623s: None
[2021-08-31 05:48:04,873: INFO/MainProcess] Received task: koytola.account.emails._send_account_confirmation_email[3484a615-2bd2-41dc-9039-c5f2bdd404bb]  
[2021-08-31 05:48:06,734: INFO/ForkPoolWorker-1] Task koytola.account.emails._send_account_confirmation_email[3484a615-2bd2-41dc-9039-c5f2bdd404bb] succeeded in 1.8600580366328359s: None
[2021-08-31 06:15:47,076: INFO/MainProcess] Received task: koytola.account.emails._send_account_confirmation_email[333be8a3-ee4d-4609-bac4-9fadb6d7eaa0]  
[2021-08-31 06:15:48,548: INFO/ForkPoolWorker-1] Task koytola.account.emails._send_account_confirmation_email[333be8a3-ee4d-4609-bac4-9fadb6d7eaa0] succeeded in 1.4704446215182543s: None
[2021-08-31 06:34:36,834: INFO/MainProcess] Received task: koytola.account.emails._send_account_confirmation_email[de415209-b1cb-4192-97e8-073d9eb0e03c]  
[2021-08-31 06:34:37,988: INFO/ForkPoolWorker-1] Task koytola.account.emails._send_account_confirmation_email[de415209-b1cb-4192-97e8-073d9eb0e03c] succeeded in 1.1492759669199586s: None
[2021-08-31 10:39:49,848: INFO/MainProcess] Received task: koytola.account.emails._send_account_confirmation_email[80646be1-3d80-4ac8-8ee0-cad36b5dd318]  
[2021-08-31 10:39:50,858: INFO/ForkPoolWorker-1] Task koytola.account.emails._send_account_confirmation_email[80646be1-3d80-4ac8-8ee0-cad36b5dd318] succeeded in 0.9957147659733891s: None
[2021-09-02 07:33:52,219: INFO/MainProcess] Received task: koytola.account.emails._send_account_confirmation_email[95846cba-0c35-4f57-b197-ebe7eb8a14f1]  
[2021-09-02 07:33:54,251: INFO/ForkPoolWorker-1] Task koytola.account.emails._send_account_confirmation_email[95846cba-0c35-4f57-b197-ebe7eb8a14f1] succeeded in 2.028493393212557s: None
[2021-09-02 08:50:53,079: INFO/MainProcess] Received task: koytola.account.emails._send_account_confirmation_email[b10c7de7-e849-4e64-91a6-d19166ffc3e0]  
[2021-09-02 08:50:54,791: INFO/ForkPoolWorker-1] Task koytola.account.emails._send_account_confirmation_email[b10c7de7-e849-4e64-91a6-d19166ffc3e0] succeeded in 1.7089645871892571s: None
[2021-09-03 08:52:26,219: INFO/MainProcess] Received task: koytola.account.emails._send_account_confirmation_email[69441b98-8406-44fc-928b-3e8c0b26ba0c]  
[2021-09-03 08:52:27,962: INFO/ForkPoolWorker-1] Task koytola.account.emails._send_account_confirmation_email[69441b98-8406-44fc-928b-3e8c0b26ba0c] succeeded in 1.7399632977321744s: None
[2021-09-03 11:29:20,479: INFO/MainProcess] Received task: koytola.account.emails._send_account_confirmation_email[3912754b-7301-4bd0-aa41-f1b82f195374]  
[2021-09-03 11:29:21,986: INFO/ForkPoolWorker-1] Task koytola.account.emails._send_account_confirmation_email[3912754b-7301-4bd0-aa41-f1b82f195374] succeeded in 1.5052350470796227s: None
[2021-09-03 11:36:16,800: INFO/MainProcess] Received task: koytola.account.emails._send_account_confirmation_email[ab5d7efd-d472-493e-ae97-6ce44d256b1b]  
[2021-09-03 11:36:18,011: INFO/ForkPoolWorker-1] Task koytola.account.emails._send_account_confirmation_email[ab5d7efd-d472-493e-ae97-6ce44d256b1b] succeeded in 1.2087687980383635s: None
[2021-09-03 11:41:47,771: INFO/MainProcess] Received task: koytola.account.emails._send_account_confirmation_email[8bab6c95-3a68-48bb-8ca3-442d08ccfc1a]  
[2021-09-03 11:41:48,928: INFO/ForkPoolWorker-1] Task koytola.account.emails._send_account_confirmation_email[8bab6c95-3a68-48bb-8ca3-442d08ccfc1a] succeeded in 1.153751608915627s: None
[2021-09-03 11:43:19,367: INFO/MainProcess] Received task: koytola.account.emails._send_account_confirmation_email[c93c88bb-440b-40da-a89b-3cad9e4a08f6]  
[2021-09-03 11:43:20,271: INFO/ForkPoolWorker-1] Task koytola.account.emails._send_account_confirmation_email[c93c88bb-440b-40da-a89b-3cad9e4a08f6] succeeded in 0.90138054266572s: None
[2021-09-03 12:14:15,546: INFO/MainProcess] Received task: koytola.account.emails._send_account_confirmation_email[caf07333-34b7-4240-bd00-81aab89ccd1e]  
[2021-09-03 12:14:16,974: INFO/ForkPoolWorker-1] Task koytola.account.emails._send_account_confirmation_email[caf07333-34b7-4240-bd00-81aab89ccd1e] succeeded in 1.4264680435881019s: None
[2021-09-03 12:26:51,582: INFO/MainProcess] Received task: koytola.account.emails._send_account_confirmation_email[9b89272f-9e3b-4119-a728-fdc78c8e4a62]  
[2021-09-03 12:26:52,855: ERROR/ForkPoolWorker-1] Task koytola.account.emails._send_account_confirmation_email[9b89272f-9e3b-4119-a728-fdc78c8e4a62] raised unexpected: SMTPDataError(451, b'4.3.0 Mail server temporarily rejected message. h4sm6258993pjc.28 - gsmtp')
Traceback (most recent call last):
  File "/home/olcaey/koytola/venv/lib/python3.8/site-packages/celery/app/trace.py", line 412, in trace_task
    R = retval = fun(*args, **kwargs)
  File "/home/olcaey/koytola/venv/lib/python3.8/site-packages/celery/app/trace.py", line 704, in __protected_call__
    return self.run(*args, **kwargs)
  File "/home/olcaey/koytola/koytola/account/emails.py", line 35, in _send_account_confirmation_email
    send_templated_mail(
  File "/home/olcaey/koytola/venv/lib/python3.8/site-packages/templated_email/__init__.py", line 68, in send_templated_mail
    return connection.send(template_name, from_email, recipient_list, context,
  File "/home/olcaey/koytola/venv/lib/python3.8/site-packages/templated_email/backends/vanilla_django.py", line 263, in send
    e.send(fail_silently)
  File "/home/olcaey/koytola/venv/lib/python3.8/site-packages/django/core/mail/message.py", line 284, in send
    return self.get_connection(fail_silently).send_messages([self])
  File "/home/olcaey/koytola/venv/lib/python3.8/site-packages/django/core/mail/backends/smtp.py", line 109, in send_messages
    sent = self._send(message)
  File "/home/olcaey/koytola/venv/lib/python3.8/site-packages/django/core/mail/backends/smtp.py", line 125, in _send
    self.connection.sendmail(from_email, recipients, message.as_bytes(linesep='\r\n'))
  File "/usr/lib/python3.8/smtplib.py", line 901, in sendmail
    raise SMTPDataError(code, resp)
smtplib.SMTPDataError: (451, b'4.3.0 Mail server temporarily rejected message. h4sm6258993pjc.28 - gsmtp')
/home/olcaey/koytola/venv/lib/python3.8/site-packages/graphene_django/types.py:94: UserWarning: Field name "description" doesn't exist on Django model "profile.Certificate". Consider removing the field from the "fields" list of DjangoObjectType "Certificate" because it has no effect.
  warnings.warn(
/home/olcaey/koytola/venv/lib/python3.8/site-packages/graphene_django/types.py:94: UserWarning: Field name "is_closed" doesn't exist on Django model "product.ProductQuery". Consider removing the field from the "fields" list of DjangoObjectType "ProductQuery" because it has no effect.
  warnings.warn(
/home/olcaey/koytola/venv/lib/python3.8/site-packages/graphene_django/types.py:94: UserWarning: Field name "content" doesn't exist on Django model "blog.Blog". Consider removing the field from the "fields" list of DjangoObjectType "BlogTranslatableContent" because it has no effect.
  warnings.warn(
/home/olcaey/koytola/venv/lib/python3.8/site-packages/graphene_django/types.py:94: UserWarning: Field name "summary" doesn't exist on Django model "blog.Blog". Consider removing the field from the "fields" list of DjangoObjectType "BlogTranslatableContent" because it has no effect.
  warnings.warn(
/home/olcaey/koytola/venv/lib/python3.8/site-packages/graphene_django/types.py:94: UserWarning: Field name "content_plaintext" doesn't exist on Django model "news.News". Consider removing the field from the "fields" list of DjangoObjectType "NewsTranslatableContent" because it has no effect.
  warnings.warn(
/home/olcaey/koytola/venv/lib/python3.8/site-packages/graphene_django/types.py:94: UserWarning: Field name "description" doesn't exist on Django model "news.News". Consider removing the field from the "fields" list of DjangoObjectType "News" because it has no effect.
  warnings.warn(
[2021-09-15 09:21:29,570: ERROR/MainProcess] consumer: Cannot connect to redis://localhost:6379/1: Error 111 connecting to localhost:6379. Connection refused..
Trying again in 2.00 seconds... (1/100)

/home/olcaey/koytola/venv/lib/python3.8/site-packages/graphene_django/types.py:94: UserWarning: Field name "description" doesn't exist on Django model "profile.Certificate". Consider removing the field from the "fields" list of DjangoObjectType "Certificate" because it has no effect.
  warnings.warn(
/home/olcaey/koytola/venv/lib/python3.8/site-packages/graphene_django/types.py:94: UserWarning: Field name "is_closed" doesn't exist on Django model "product.ProductQuery". Consider removing the field from the "fields" list of DjangoObjectType "ProductQuery" because it has no effect.
  warnings.warn(
/home/olcaey/koytola/venv/lib/python3.8/site-packages/graphene_django/types.py:94: UserWarning: Field name "content" doesn't exist on Django model "blog.Blog". Consider removing the field from the "fields" list of DjangoObjectType "BlogTranslatableContent" because it has no effect.
  warnings.warn(
/home/olcaey/koytola/venv/lib/python3.8/site-packages/graphene_django/types.py:94: UserWarning: Field name "summary" doesn't exist on Django model "blog.Blog". Consider removing the field from the "fields" list of DjangoObjectType "BlogTranslatableContent" because it has no effect.
  warnings.warn(
/home/olcaey/koytola/venv/lib/python3.8/site-packages/graphene_django/types.py:94: UserWarning: Field name "content_plaintext" doesn't exist on Django model "news.News". Consider removing the field from the "fields" list of DjangoObjectType "NewsTranslatableContent" because it has no effect.
  warnings.warn(
/home/olcaey/koytola/venv/lib/python3.8/site-packages/graphene_django/types.py:94: UserWarning: Field name "description" doesn't exist on Django model "news.News". Consider removing the field from the "fields" list of DjangoObjectType "News" because it has no effect.
  warnings.warn(
[2021-09-15 09:21:29,783: ERROR/MainProcess] consumer: Cannot connect to redis://localhost:6379/1: Error 111 connecting to localhost:6379. Connection refused..
Trying again in 2.00 seconds... (1/100)

/home/olcaey/koytola/venv/lib/python3.8/site-packages/graphene_django/types.py:94: UserWarning: Field name "description" doesn't exist on Django model "profile.Certificate". Consider removing the field from the "fields" list of DjangoObjectType "Certificate" because it has no effect.
  warnings.warn(
/home/olcaey/koytola/venv/lib/python3.8/site-packages/graphene_django/types.py:94: UserWarning: Field name "is_closed" doesn't exist on Django model "product.ProductQuery". Consider removing the field from the "fields" list of DjangoObjectType "ProductQuery" because it has no effect.
  warnings.warn(
/home/olcaey/koytola/venv/lib/python3.8/site-packages/graphene_django/types.py:94: UserWarning: Field name "content" doesn't exist on Django model "blog.Blog". Consider removing the field from the "fields" list of DjangoObjectType "BlogTranslatableContent" because it has no effect.
  warnings.warn(
/home/olcaey/koytola/venv/lib/python3.8/site-packages/graphene_django/types.py:94: UserWarning: Field name "summary" doesn't exist on Django model "blog.Blog". Consider removing the field from the "fields" list of DjangoObjectType "BlogTranslatableContent" because it has no effect.
  warnings.warn(
/home/olcaey/koytola/venv/lib/python3.8/site-packages/graphene_django/types.py:94: UserWarning: Field name "content_plaintext" doesn't exist on Django model "news.News". Consider removing the field from the "fields" list of DjangoObjectType "NewsTranslatableContent" because it has no effect.
  warnings.warn(
/home/olcaey/koytola/venv/lib/python3.8/site-packages/graphene_django/types.py:94: UserWarning: Field name "description" doesn't exist on Django model "news.News". Consider removing the field from the "fields" list of DjangoObjectType "News" because it has no effect.
  warnings.warn(
[2021-09-15 09:21:29,794: ERROR/MainProcess] consumer: Cannot connect to redis://localhost:6379/1: Error 111 connecting to localhost:6379. Connection refused..
Trying again in 2.00 seconds... (1/100)

/home/olcaey/koytola/venv/lib/python3.8/site-packages/graphene_django/types.py:94: UserWarning: Field name "description" doesn't exist on Django model "profile.Certificate". Consider removing the field from the "fields" list of DjangoObjectType "Certificate" because it has no effect.
  warnings.warn(
/home/olcaey/koytola/venv/lib/python3.8/site-packages/graphene_django/types.py:94: UserWarning: Field name "is_closed" doesn't exist on Django model "product.ProductQuery". Consider removing the field from the "fields" list of DjangoObjectType "ProductQuery" because it has no effect.
  warnings.warn(
/home/olcaey/koytola/venv/lib/python3.8/site-packages/graphene_django/types.py:94: UserWarning: Field name "content" doesn't exist on Django model "blog.Blog". Consider removing the field from the "fields" list of DjangoObjectType "BlogTranslatableContent" because it has no effect.
  warnings.warn(
/home/olcaey/koytola/venv/lib/python3.8/site-packages/graphene_django/types.py:94: UserWarning: Field name "summary" doesn't exist on Django model "blog.Blog". Consider removing the field from the "fields" list of DjangoObjectType "BlogTranslatableContent" because it has no effect.
  warnings.warn(
/home/olcaey/koytola/venv/lib/python3.8/site-packages/graphene_django/types.py:94: UserWarning: Field name "content_plaintext" doesn't exist on Django model "news.News". Consider removing the field from the "fields" list of DjangoObjectType "NewsTranslatableContent" because it has no effect.
  warnings.warn(
/home/olcaey/koytola/venv/lib/python3.8/site-packages/graphene_django/types.py:94: UserWarning: Field name "description" doesn't exist on Django model "news.News". Consider removing the field from the "fields" list of DjangoObjectType "News" because it has no effect.
  warnings.warn(
[2021-09-15 09:21:29,801: ERROR/MainProcess] consumer: Cannot connect to redis://localhost:6379/1: Error 111 connecting to localhost:6379. Connection refused..
Trying again in 2.00 seconds... (1/100)

/home/olcaey/koytola/venv/lib/python3.8/site-packages/graphene_django/types.py:94: UserWarning: Field name "description" doesn't exist on Django model "profile.Certificate". Consider removing the field from the "fields" list of DjangoObjectType "Certificate" because it has no effect.
  warnings.warn(
/home/olcaey/koytola/venv/lib/python3.8/site-packages/graphene_django/types.py:94: UserWarning: Field name "is_closed" doesn't exist on Django model "product.ProductQuery". Consider removing the field from the "fields" list of DjangoObjectType "ProductQuery" because it has no effect.
  warnings.warn(
/home/olcaey/koytola/venv/lib/python3.8/site-packages/graphene_django/types.py:94: UserWarning: Field name "content" doesn't exist on Django model "blog.Blog". Consider removing the field from the "fields" list of DjangoObjectType "BlogTranslatableContent" because it has no effect.
  warnings.warn(
/home/olcaey/koytola/venv/lib/python3.8/site-packages/graphene_django/types.py:94: UserWarning: Field name "summary" doesn't exist on Django model "blog.Blog". Consider removing the field from the "fields" list of DjangoObjectType "BlogTranslatableContent" because it has no effect.
  warnings.warn(
/home/olcaey/koytola/venv/lib/python3.8/site-packages/graphene_django/types.py:94: UserWarning: Field name "content_plaintext" doesn't exist on Django model "news.News". Consider removing the field from the "fields" list of DjangoObjectType "NewsTranslatableContent" because it has no effect.
  warnings.warn(
/home/olcaey/koytola/venv/lib/python3.8/site-packages/graphene_django/types.py:94: UserWarning: Field name "description" doesn't exist on Django model "news.News". Consider removing the field from the "fields" list of DjangoObjectType "News" because it has no effect.
  warnings.warn(
[2021-09-15 09:21:29,824: ERROR/MainProcess] consumer: Cannot connect to redis://localhost:6379/1: Error 111 connecting to localhost:6379. Connection refused..
Trying again in 2.00 seconds... (1/100)

/home/olcaey/koytola/venv/lib/python3.8/site-packages/graphene_django/types.py:94: UserWarning: Field name "description" doesn't exist on Django model "profile.Certificate". Consider removing the field from the "fields" list of DjangoObjectType "Certificate" because it has no effect.
  warnings.warn(
/home/olcaey/koytola/venv/lib/python3.8/site-packages/graphene_django/types.py:94: UserWarning: Field name "is_closed" doesn't exist on Django model "product.ProductQuery". Consider removing the field from the "fields" list of DjangoObjectType "ProductQuery" because it has no effect.
  warnings.warn(
/home/olcaey/koytola/venv/lib/python3.8/site-packages/graphene_django/types.py:94: UserWarning: Field name "content" doesn't exist on Django model "blog.Blog". Consider removing the field from the "fields" list of DjangoObjectType "BlogTranslatableContent" because it has no effect.
  warnings.warn(
/home/olcaey/koytola/venv/lib/python3.8/site-packages/graphene_django/types.py:94: UserWarning: Field name "summary" doesn't exist on Django model "blog.Blog". Consider removing the field from the "fields" list of DjangoObjectType "BlogTranslatableContent" because it has no effect.
  warnings.warn(
/home/olcaey/koytola/venv/lib/python3.8/site-packages/graphene_django/types.py:94: UserWarning: Field name "content_plaintext" doesn't exist on Django model "news.News". Consider removing the field from the "fields" list of DjangoObjectType "NewsTranslatableContent" because it has no effect.
  warnings.warn(
/home/olcaey/koytola/venv/lib/python3.8/site-packages/graphene_django/types.py:94: UserWarning: Field name "description" doesn't exist on Django model "news.News". Consider removing the field from the "fields" list of DjangoObjectType "News" because it has no effect.
  warnings.warn(
[2021-09-15 09:21:29,870: ERROR/MainProcess] consumer: Cannot connect to redis://localhost:6379/1: Error 111 connecting to localhost:6379. Connection refused..
Trying again in 2.00 seconds... (1/100)

/home/olcaey/koytola/venv/lib/python3.8/site-packages/graphene_django/types.py:94: UserWarning: Field name "description" doesn't exist on Django model "profile.Certificate". Consider removing the field from the "fields" list of DjangoObjectType "Certificate" because it has no effect.
  warnings.warn(
/home/olcaey/koytola/venv/lib/python3.8/site-packages/graphene_django/types.py:94: UserWarning: Field name "is_closed" doesn't exist on Django model "product.ProductQuery". Consider removing the field from the "fields" list of DjangoObjectType "ProductQuery" because it has no effect.
  warnings.warn(
/home/olcaey/koytola/venv/lib/python3.8/site-packages/graphene_django/types.py:94: UserWarning: Field name "content" doesn't exist on Django model "blog.Blog". Consider removing the field from the "fields" list of DjangoObjectType "BlogTranslatableContent" because it has no effect.
  warnings.warn(
/home/olcaey/koytola/venv/lib/python3.8/site-packages/graphene_django/types.py:94: UserWarning: Field name "summary" doesn't exist on Django model "blog.Blog". Consider removing the field from the "fields" list of DjangoObjectType "BlogTranslatableContent" because it has no effect.
  warnings.warn(
/home/olcaey/koytola/venv/lib/python3.8/site-packages/graphene_django/types.py:94: UserWarning: Field name "content_plaintext" doesn't exist on Django model "news.News". Consider removing the field from the "fields" list of DjangoObjectType "NewsTranslatableContent" because it has no effect.
  warnings.warn(
/home/olcaey/koytola/venv/lib/python3.8/site-packages/graphene_django/types.py:94: UserWarning: Field name "description" doesn't exist on Django model "news.News". Consider removing the field from the "fields" list of DjangoObjectType "News" because it has no effect.
  warnings.warn(
[2021-09-15 09:21:29,934: ERROR/MainProcess] consumer: Cannot connect to redis://localhost:6379/1: Error 111 connecting to localhost:6379. Connection refused..
Trying again in 2.00 seconds... (1/100)

[2021-09-15 09:21:31,597: ERROR/MainProcess] consumer: Cannot connect to redis://localhost:6379/1: Error 111 connecting to localhost:6379. Connection refused..
Trying again in 4.00 seconds... (2/100)

[2021-09-15 09:21:31,788: ERROR/MainProcess] consumer: Cannot connect to redis://localhost:6379/1: Error 111 connecting to localhost:6379. Connection refused..
Trying again in 4.00 seconds... (2/100)

[2021-09-15 09:21:31,799: ERROR/MainProcess] consumer: Cannot connect to redis://localhost:6379/1: Error 111 connecting to localhost:6379. Connection refused..
Trying again in 4.00 seconds... (2/100)

[2021-09-15 09:21:31,806: ERROR/MainProcess] consumer: Cannot connect to redis://localhost:6379/1: Error 111 connecting to localhost:6379. Connection refused..
Trying again in 4.00 seconds... (2/100)

[2021-09-15 09:21:31,829: ERROR/MainProcess] consumer: Cannot connect to redis://localhost:6379/1: Error 111 connecting to localhost:6379. Connection refused..
Trying again in 4.00 seconds... (2/100)

[2021-09-15 09:21:31,875: ERROR/MainProcess] consumer: Cannot connect to redis://localhost:6379/1: Error 111 connecting to localhost:6379. Connection refused..
Trying again in 4.00 seconds... (2/100)

[2021-09-15 09:21:31,939: ERROR/MainProcess] consumer: Cannot connect to redis://localhost:6379/1: Error 111 connecting to localhost:6379. Connection refused..
Trying again in 4.00 seconds... (2/100)

[2021-09-15 09:21:35,604: ERROR/MainProcess] consumer: Cannot connect to redis://localhost:6379/1: Error 111 connecting to localhost:6379. Connection refused..
Trying again in 6.00 seconds... (3/100)

[2021-09-15 09:21:35,794: ERROR/MainProcess] consumer: Cannot connect to redis://localhost:6379/1: Error 111 connecting to localhost:6379. Connection refused..
Trying again in 6.00 seconds... (3/100)

[2021-09-15 09:21:35,806: ERROR/MainProcess] consumer: Cannot connect to redis://localhost:6379/1: Error 111 connecting to localhost:6379. Connection refused..
Trying again in 6.00 seconds... (3/100)

[2021-09-15 09:21:35,812: ERROR/MainProcess] consumer: Cannot connect to redis://localhost:6379/1: Error 111 connecting to localhost:6379. Connection refused..
Trying again in 6.00 seconds... (3/100)

[2021-09-15 09:21:35,835: ERROR/MainProcess] consumer: Cannot connect to redis://localhost:6379/1: Error 111 connecting to localhost:6379. Connection refused..
Trying again in 6.00 seconds... (3/100)

[2021-09-15 09:21:35,882: ERROR/MainProcess] consumer: Cannot connect to redis://localhost:6379/1: Error 111 connecting to localhost:6379. Connection refused..
Trying again in 6.00 seconds... (3/100)

[2021-09-15 09:21:35,946: ERROR/MainProcess] consumer: Cannot connect to redis://localhost:6379/1: Error 111 connecting to localhost:6379. Connection refused..
Trying again in 6.00 seconds... (3/100)

[2021-09-15 09:21:41,612: ERROR/MainProcess] consumer: Cannot connect to redis://localhost:6379/1: Error 111 connecting to localhost:6379. Connection refused..
Trying again in 8.00 seconds... (4/100)

[2021-09-15 09:21:41,803: ERROR/MainProcess] consumer: Cannot connect to redis://localhost:6379/1: Error 111 connecting to localhost:6379. Connection refused..
Trying again in 8.00 seconds... (4/100)

[2021-09-15 09:21:41,814: ERROR/MainProcess] consumer: Cannot connect to redis://localhost:6379/1: Error 111 connecting to localhost:6379. Connection refused..
Trying again in 8.00 seconds... (4/100)

[2021-09-15 09:21:41,820: ERROR/MainProcess] consumer: Cannot connect to redis://localhost:6379/1: Error 111 connecting to localhost:6379. Connection refused..
Trying again in 8.00 seconds... (4/100)

[2021-09-15 09:21:41,844: ERROR/MainProcess] consumer: Cannot connect to redis://localhost:6379/1: Error 111 connecting to localhost:6379. Connection refused..
Trying again in 8.00 seconds... (4/100)

[2021-09-15 09:21:41,891: ERROR/MainProcess] consumer: Cannot connect to redis://localhost:6379/1: Error 111 connecting to localhost:6379. Connection refused..
Trying again in 8.00 seconds... (4/100)

[2021-09-15 09:21:41,955: ERROR/MainProcess] consumer: Cannot connect to redis://localhost:6379/1: Error 111 connecting to localhost:6379. Connection refused..
Trying again in 8.00 seconds... (4/100)

[2021-09-15 09:21:49,623: ERROR/MainProcess] consumer: Cannot connect to redis://localhost:6379/1: Error 111 connecting to localhost:6379. Connection refused..
Trying again in 10.00 seconds... (5/100)

[2021-09-15 09:21:49,814: ERROR/MainProcess] consumer: Cannot connect to redis://localhost:6379/1: Error 111 connecting to localhost:6379. Connection refused..
Trying again in 10.00 seconds... (5/100)

[2021-09-15 09:21:49,825: ERROR/MainProcess] consumer: Cannot connect to redis://localhost:6379/1: Error 111 connecting to localhost:6379. Connection refused..
Trying again in 10.00 seconds... (5/100)

[2021-09-15 09:21:49,831: ERROR/MainProcess] consumer: Cannot connect to redis://localhost:6379/1: Error 111 connecting to localhost:6379. Connection refused..
Trying again in 10.00 seconds... (5/100)

[2021-09-15 09:21:49,856: ERROR/MainProcess] consumer: Cannot connect to redis://localhost:6379/1: Error 111 connecting to localhost:6379. Connection refused..
Trying again in 10.00 seconds... (5/100)

[2021-09-15 09:21:49,902: ERROR/MainProcess] consumer: Cannot connect to redis://localhost:6379/1: Error 111 connecting to localhost:6379. Connection refused..
Trying again in 10.00 seconds... (5/100)

[2021-09-15 09:21:49,966: ERROR/MainProcess] consumer: Cannot connect to redis://localhost:6379/1: Error 111 connecting to localhost:6379. Connection refused..
Trying again in 10.00 seconds... (5/100)

[2021-09-15 09:21:59,637: ERROR/MainProcess] consumer: Cannot connect to redis://localhost:6379/1: Error 111 connecting to localhost:6379. Connection refused..
Trying again in 12.00 seconds... (6/100)

[2021-09-15 09:21:59,827: ERROR/MainProcess] consumer: Cannot connect to redis://localhost:6379/1: Error 111 connecting to localhost:6379. Connection refused..
Trying again in 12.00 seconds... (6/100)

[2021-09-15 09:21:59,838: ERROR/MainProcess] consumer: Cannot connect to redis://localhost:6379/1: Error 111 connecting to localhost:6379. Connection refused..
Trying again in 12.00 seconds... (6/100)

[2021-09-15 09:21:59,844: ERROR/MainProcess] consumer: Cannot connect to redis://localhost:6379/1: Error 111 connecting to localhost:6379. Connection refused..
Trying again in 12.00 seconds... (6/100)

[2021-09-15 09:21:59,869: ERROR/MainProcess] consumer: Cannot connect to redis://localhost:6379/1: Error 111 connecting to localhost:6379. Connection refused..
Trying again in 12.00 seconds... (6/100)

[2021-09-15 09:21:59,915: ERROR/MainProcess] consumer: Cannot connect to redis://localhost:6379/1: Error 111 connecting to localhost:6379. Connection refused..
Trying again in 12.00 seconds... (6/100)

[2021-09-15 09:21:59,979: ERROR/MainProcess] consumer: Cannot connect to redis://localhost:6379/1: Error 111 connecting to localhost:6379. Connection refused..
Trying again in 12.00 seconds... (6/100)

[2021-09-15 09:22:11,652: ERROR/MainProcess] consumer: Cannot connect to redis://localhost:6379/1: Error 111 connecting to localhost:6379. Connection refused..
Trying again in 14.00 seconds... (7/100)

[2021-09-15 09:22:11,842: ERROR/MainProcess] consumer: Cannot connect to redis://localhost:6379/1: Error 111 connecting to localhost:6379. Connection refused..
Trying again in 14.00 seconds... (7/100)

[2021-09-15 09:22:11,853: ERROR/MainProcess] consumer: Cannot connect to redis://localhost:6379/1: Error 111 connecting to localhost:6379. Connection refused..
Trying again in 14.00 seconds... (7/100)

[2021-09-15 09:22:11,859: ERROR/MainProcess] consumer: Cannot connect to redis://localhost:6379/1: Error 111 connecting to localhost:6379. Connection refused..
Trying again in 14.00 seconds... (7/100)

[2021-09-15 09:22:11,884: ERROR/MainProcess] consumer: Cannot connect to redis://localhost:6379/1: Error 111 connecting to localhost:6379. Connection refused..
Trying again in 14.00 seconds... (7/100)

[2021-09-15 09:22:11,931: ERROR/MainProcess] consumer: Cannot connect to redis://localhost:6379/1: Error 111 connecting to localhost:6379. Connection refused..
Trying again in 14.00 seconds... (7/100)

[2021-09-15 09:22:11,995: ERROR/MainProcess] consumer: Cannot connect to redis://localhost:6379/1: Error 111 connecting to localhost:6379. Connection refused..
Trying again in 14.00 seconds... (7/100)

[2021-09-15 09:22:25,669: ERROR/MainProcess] consumer: Cannot connect to redis://localhost:6379/1: Error 111 connecting to localhost:6379. Connection refused..
Trying again in 16.00 seconds... (8/100)

[2021-09-15 09:22:25,859: ERROR/MainProcess] consumer: Cannot connect to redis://localhost:6379/1: Error 111 connecting to localhost:6379. Connection refused..
Trying again in 16.00 seconds... (8/100)

[2021-09-15 09:22:25,869: ERROR/MainProcess] consumer: Cannot connect to redis://localhost:6379/1: Error 111 connecting to localhost:6379. Connection refused..
Trying again in 16.00 seconds... (8/100)

[2021-09-15 09:22:25,876: ERROR/MainProcess] consumer: Cannot connect to redis://localhost:6379/1: Error 111 connecting to localhost:6379. Connection refused..
Trying again in 16.00 seconds... (8/100)

[2021-09-15 09:22:25,901: ERROR/MainProcess] consumer: Cannot connect to redis://localhost:6379/1: Error 111 connecting to localhost:6379. Connection refused..
Trying again in 16.00 seconds... (8/100)

[2021-09-15 09:22:25,948: ERROR/MainProcess] consumer: Cannot connect to redis://localhost:6379/1: Error 111 connecting to localhost:6379. Connection refused..
Trying again in 16.00 seconds... (8/100)

[2021-09-15 09:22:26,012: ERROR/MainProcess] consumer: Cannot connect to redis://localhost:6379/1: Error 111 connecting to localhost:6379. Connection refused..
Trying again in 16.00 seconds... (8/100)

